<?xml version="1.0" ?>
<robot name="arm"
  xmlns:xacro="http://www.ros.org/wiki/xacro">

  <!-- 
 Regular Expressions
    Find - xyz="(.+)\s(.+)\s(.+)" r
    Replace - xyz="$1 $2 ${sign*$3}" r

    Find
      <inertia\s+ixx="([^"]+)"\s+iyy="([^"]+)"\s+izz="([^"]+)"\s+ixy="([^"]+)"\s+iyz="([^"]+)"\s+ixz="([^"]+)"\s*/>
    Replace
      <inertia ixx="$1" iyy="$2" izz="$3" ixy="${sign*$4}" iyz="${sign*$5}" ixz="$6"/>

      hyperspawn_dropbear_description/meshes/${folder}

      link name="${prefix}_
      joint name="${prefix}_
   -->

    <xacro:macro name="arm_macro" params="prefix folder parent sign *origin">
        <!-- <link name="${prefix}_base_link">
          <inertial>
            <origin xyz="-4.564684959507811e-14 -1.297744842251468e-14 ${sign*-0.00040000000000051}" rpy="0 0 0"/>
            <mass value="0.0710251267123582"/>
            <inertia ixx="1.03755872605632e-05" iyy="1.03755872605639e-05" izz="2.04552364931589e-05" ixy="${sign*2.231104194494098e-20}" iyz="${sign*-3.993969333038147e-17}" ixz="8.809863505376990e-17"/>
          </inertial>
          <visual>
            <origin xyz="0 0 ${sign*0}" rpy="0 0 0"/>
            <geometry>
              <mesh filename="package://hyperspawn_dropbear_description/meshes/${folder}/base_link.stl" scale="0.001 0.001 0.001"/>
            </geometry>
            <material name="opaque2550255"/>
          </visual>
          <collision>
            <origin xyz="0 0 ${sign*0}" rpy="0 0 0"/>
            <geometry>
              <mesh filename="package://hyperspawn_dropbear_description/meshes/${folder}/base_link.stl" scale="0.001 0.001 0.001"/>
            </geometry>
          </collision>
        </link> -->
        
        <link name="${prefix}_2020_100mm__9__1">
          <inertial>
            <origin xyz="1.4980442800229068e-14 5.199887469533773e-15 ${sign*0.049999999999999795}" rpy="0 0 0"/>
            <mass value="0.019591747444562"/>
            <inertia ixx="1.71247911414457e-05" iyy="1.71247911416276e-05" izz="1.59666987542057e-06" ixy="${sign*-6.394884621840706e-17}" iyz="${sign*2.518172085831656e-18}" ixz="7.829445091340370e-18"/>
          </inertial>
          <visual>
            <origin xyz="0.0 0.0 ${sign*-0.0021}" rpy="0 0 0"/>
            <geometry>
              <mesh filename="package://hyperspawn_dropbear_description/meshes/${folder}/2020_100mm__9__1.stl" scale="0.001 0.001 0.001"/>
            </geometry>
            <material name="opaque727161"/>
          </visual>
          <collision>
            <origin xyz="0.0 0.0 ${sign*-0.0021}" rpy="0 0 0"/>
            <geometry>
              <mesh filename="package://hyperspawn_dropbear_description/meshes/${folder}/2020_100mm__9__1.stl" scale="0.001 0.001 0.001"/>
            </geometry>
          </collision>
        </link>
        
        <link name="${prefix}_shoulder-roll-al-mot_MIR1__1__1">
          <inertial>
            <origin xyz="0.005127204279605231 -0.01578027268886943 ${sign*0.013349013943228552}" rpy="0 0 0"/>
            <mass value="0.0139822805624322"/>
            <inertia ixx="1.33357850186962e-06" iyy="2.39192509601408e-06" izz="1.95321408998418e-06" ixy="${sign*-3.84446207640792e-07}" iyz="${sign*1.4147058742276e-08}" ixz="-4.62978754176702e-09"/>
          </inertial>
          <visual>
            <origin xyz="0.0 -0.0 ${sign*-0.0021}" rpy="0 0 0"/>
            <geometry>
              <mesh filename="package://hyperspawn_dropbear_description/meshes/${folder}/shoulder-roll-al-mot_MIR1__1__1.stl" scale="0.001 0.001 0.001"/>
            </geometry>
            <material name="opaque245245245"/>
          </visual>
          <collision>
            <origin xyz="0.0 -0.0 ${sign*-0.0021}" rpy="0 0 0"/>
            <geometry>
              <mesh filename="package://hyperspawn_dropbear_description/meshes/${folder}/shoulder-roll-al-mot_MIR1__1__1.stl" scale="0.001 0.001 0.001"/>
            </geometry>
          </collision>
        </link>
        
        <link name="${prefix}_shoulder-roll-al-mot_MIR1__2__1">
          <inertial>
            <origin xyz="-0.005127204279607458 0.015780272688869185 ${sign*0.013349013943228556}" rpy="0 0 0"/>
            <mass value="0.0139822805624322"/>
            <inertia ixx="1.33357850186963e-06" iyy="2.39192509601406e-06" izz="1.95321408998418e-06" ixy="${sign*-3.84446207640812e-07}" iyz="${sign*-1.41470587422785e-08}" ixz="4.62978754176003e-09"/>
          </inertial>
          <visual>
            <origin xyz="0.0 -0.0 ${sign*-0.0021}" rpy="0 0 0"/>
            <geometry>
              <mesh filename="package://hyperspawn_dropbear_description/meshes/${folder}/shoulder-roll-al-mot_MIR1__2__1.stl" scale="0.001 0.001 0.001"/>
            </geometry>
            <material name="opaque245245245"/>
          </visual>
          <collision>
            <origin xyz="0.0 -0.0 ${sign*-0.0021}" rpy="0 0 0"/>
            <geometry>
              <mesh filename="package://hyperspawn_dropbear_description/meshes/${folder}/shoulder-roll-al-mot_MIR1__2__1.stl" scale="0.001 0.001 0.001"/>
            </geometry>
          </collision>
        </link>
        
        <link name="${prefix}_yaw-cap_1">
          <inertial>
            <origin xyz="-8.404754804490673e-15 2.1068804545096473e-14 ${sign*-0.006586829858195878}" rpy="0 0 0"/>
            <mass value="0.0147970811486"/>
            <inertia ixx="2.47144498176233e-06" iyy="4.12036554274002e-06" izz="2.86340658923296e-06" ixy="${sign*-5.99005456426396e-07}" iyz="${sign*2.946851009227335e-18}" ixz="-1.059818412580698e-18"/>
          </inertial>
          <visual>
            <origin xyz="0.0 0.0 ${sign*-0.1021}" rpy="0 0 0"/>
            <geometry>
              <mesh filename="package://hyperspawn_dropbear_description/meshes/${folder}/yaw-cap_1.stl" scale="0.001 0.001 0.001"/>
            </geometry>
            <material name="opaque245245245"/>
          </visual>
          <collision>
            <origin xyz="0.0 0.0 ${sign*-0.1021}" rpy="0 0 0"/>
            <geometry>
              <mesh filename="package://hyperspawn_dropbear_description/meshes/${folder}/yaw-cap_1.stl" scale="0.001 0.001 0.001"/>
            </geometry>
          </collision>
        </link>
        
        <link name="${prefix}_yaw-waist-adapter-motor-exal_MIR1_1">
          <inertial>
            <origin xyz="-0.0022354396247523025 0.006879975731446575 ${sign*0.049999999999987436}" rpy="0 0 0"/>
            <mass value="0.0374132377219994"/>
            <inertia ixx="7.74698902279246e-06" iyy="1.35806331978027e-05" izz="1.28983762196582e-05" ixy="${sign*-2.11919529319787e-06}" iyz="${sign*-1.897353801849633e-19}" ixz="3.642241673193491e-20"/>
          </inertial>
          <visual>
            <origin xyz="0.0 -0.0 ${sign*-0.0021}" rpy="0 0 0"/>
            <geometry>
              <mesh filename="package://hyperspawn_dropbear_description/meshes/${folder}/yaw-waist-adapter-motor-exal_MIR1_1.stl" scale="0.001 0.001 0.001"/>
            </geometry>
            <material name="opaque245245245"/>
          </visual>
          <collision>
            <origin xyz="0.0 -0.0 ${sign*-0.0021}" rpy="0 0 0"/>
            <geometry>
              <mesh filename="package://hyperspawn_dropbear_description/meshes/${folder}/yaw-waist-adapter-motor-exal_MIR1_1.stl" scale="0.001 0.001 0.001"/>
            </geometry>
          </collision>
        </link>
        
        <link name="${prefix}_front-bearing-adapter-shoulder_1">
          <inertial>
            <origin xyz="0.012476625956564928 0.01204671407588206 ${sign*-0.00900000000002072}" rpy="0 0 0"/>
            <mass value="0.023683107739144"/>
            <inertia ixx="3.64971689005244e-06" iyy="7.09787565227239e-06" izz="5.22213010024979e-06" ixy="${sign*-1.2526169920336e-06}" iyz="${sign*9.893344823930228e-19}" ixz="-3.184843881676169e-19"/>
          </inertial>
          <visual>
            <origin xyz="0.021006 -0.014204 ${sign*-0.0611}" rpy="0 0 0"/>
            <geometry>
              <mesh filename="package://hyperspawn_dropbear_description/meshes/${folder}/front-bearing-adapter-shoulder_1.stl" scale="0.001 0.001 0.001"/>
            </geometry>
            <material name="opaque191191191"/>
          </visual>
          <collision>
            <origin xyz="0.021006 -0.014204 ${sign*-0.0611}" rpy="0 0 0"/>
            <geometry>
              <mesh filename="package://hyperspawn_dropbear_description/meshes/${folder}/front-bearing-adapter-shoulder_1.stl" scale="0.001 0.001 0.001"/>
            </geometry>
          </collision>
        </link>
        
        <link name="${prefix}_shoulder-ex-al-interface__2__1">
          <inertial>
            <origin xyz="0.01738138579865837 -0.0030497886170603797 ${sign*-0.008999999999991598}" rpy="0 0 0"/>
            <mass value="0.027893677646265"/>
            <inertia ixx="4.32482586114369e-06" iyy="8.39411157893946e-06" izz="6.30628010967354e-06" ixy="${sign*-1.47825456629198e-06}" iyz="${sign*2.466898755583424e-17}" ixz="7.404253805128741e-17"/>
          </inertial>
          <visual>
            <origin xyz="0.011735 0.014328 ${sign*-0.0611}" rpy="0 0 0"/>
            <geometry>
              <mesh filename="package://hyperspawn_dropbear_description/meshes/${folder}/shoulder-ex-al-interface__2__1.stl" scale="0.001 0.001 0.001"/>
            </geometry>
            <material name="opaque22122113"/>
          </visual>
          <collision>
            <origin xyz="0.011735 0.014328 ${sign*-0.0611}" rpy="0 0 0"/>
            <geometry>
              <mesh filename="package://hyperspawn_dropbear_description/meshes/${folder}/shoulder-ex-al-interface__2__1.stl" scale="0.001 0.001 0.001"/>
            </geometry>
          </collision>
        </link>
        
        <link name="${prefix}_RMD-X8-Pro_MIR8_MIR1__1__1">
          <inertial>
            <origin xyz="0.0067650965649745445 -0.020808521702550438 ${sign*0.00046176070349858434}" rpy="0 0 0"/>
            <mass value="0.0658409996798309"/>
            <inertia ixx="6.73245559130172e-05" iyy="9.09727241934292e-05" izz="6.35281702686579e-05" ixy="${sign*-8.59564716294938e-06}" iyz="${sign*7.14503501851588e-07}" ixz="-2.30317369534993e-07"/>
          </inertial>
          <visual>
            <origin xyz="-0.008343 0.025679 ${sign*-0.0521}" rpy="0 0 0"/>
            <geometry>
              <mesh filename="package://hyperspawn_dropbear_description/meshes/${folder}/RMD-X8-Pro_MIR8_MIR1__1__1.stl" scale="0.001 0.001 0.001"/>
            </geometry>
            <material name="opaque13110895"/>
          </visual>
          <collision>
            <origin xyz="-0.008343 0.025679 ${sign*-0.0521}" rpy="0 0 0"/>
            <geometry>
              <mesh filename="package://hyperspawn_dropbear_description/meshes/${folder}/RMD-X8-Pro_MIR8_MIR1__1__1.stl" scale="0.001 0.001 0.001"/>
            </geometry>
          </collision>
        </link>
        
        <link name="${prefix}_shoulder-motor-bicep-rotor-bracket_1">
          <inertial>
            <origin xyz="0.011585383104448774 -0.002019144805998477 ${sign*0.006894585665480131}" rpy="0 0 0"/>
            <mass value="0.0242631871440445"/>
            <inertia ixx="7.32924174579478e-06" iyy="1.01897271688699e-05" izz="4.02506203897297e-06" ixy="${sign*-1.03913215530172e-06}" iyz="${sign*-4.23772294446241e-07}" ixz="-1.30423701412823e-06"/>
          </inertial>
          <visual>
            <origin xyz="-0.059876 0.048364 ${sign*-0.0521}" rpy="0 0 0"/>
            <geometry>
              <mesh filename="package://hyperspawn_dropbear_description/meshes/${folder}/shoulder-motor-bicep-rotor-bracket_1.stl" scale="0.001 0.001 0.001"/>
            </geometry>
            <material name="opaque245245245"/>
          </visual>
          <collision>
            <origin xyz="-0.059876 0.048364 ${sign*-0.0521}" rpy="0 0 0"/>
            <geometry>
              <mesh filename="package://hyperspawn_dropbear_description/meshes/${folder}/shoulder-motor-bicep-rotor-bracket_1.stl" scale="0.001 0.001 0.001"/>
            </geometry>
          </collision>
        </link>
        
        <link name="${prefix}_bicep-rear-motor-adapter_1">
          <inertial>
            <origin xyz="-0.0018929355342764131 0.016127672677199507 ${sign*0.015500000000001603}" rpy="0 0 0"/>
            <mass value="0.0281681226709944"/>
            <inertia ixx="6.66789269228993e-06" iyy="5.24554656234814e-06" izz="6.37785740381877e-06" ixy="${sign*1.31824458087614e-06}" iyz="${sign*1.694065894508601e-19}" ixz="-5.421010862427522e-20"/>
          </inertial>
          <visual>
            <origin xyz="-0.076995 0.042802 ${sign*-0.0506}" rpy="0 0 0"/>
            <geometry>
              <mesh filename="package://hyperspawn_dropbear_description/meshes/${folder}/bicep-rear-motor-adapter_1.stl" scale="0.001 0.001 0.001"/>
            </geometry>
            <material name="opaque191191191"/>
          </visual>
          <collision>
            <origin xyz="-0.076995 0.042802 ${sign*-0.0506}" rpy="0 0 0"/>
            <geometry>
              <mesh filename="package://hyperspawn_dropbear_description/meshes/${folder}/bicep-rear-motor-adapter_1.stl" scale="0.001 0.001 0.001"/>
            </geometry>
          </collision>
        </link>
        
        <link name="${prefix}_bicep-shoulder-bracket-exal__1__1">
          <inertial>
            <origin xyz="0.011983042446585573 -0.004518260205938709 ${sign*0.005535150009386286}" rpy="0 0 0"/>
            <mass value="0.0119000299936683"/>
            <inertia ixx="1.06039831340363e-06" iyy="1.52523000194053e-06" izz="2.34706806988364e-06" ixy="${sign*-1.688599950433e-07}" iyz="${sign*6.776263578034403e-21}" ixz="1.355252715606881e-20"/>
          </inertial>
          <visual>
            <origin xyz="-0.065252 0.006662 ${sign*-0.0761}" rpy="0 0 0"/>
            <geometry>
              <mesh filename="package://hyperspawn_dropbear_description/meshes/${folder}/bicep-shoulder-bracket-exal__1__1.stl" scale="0.001 0.001 0.001"/>
            </geometry>
            <material name="opaque245245245"/>
          </visual>
          <collision>
            <origin xyz="-0.065252 0.006662 ${sign*-0.0761}" rpy="0 0 0"/>
            <geometry>
              <mesh filename="package://hyperspawn_dropbear_description/meshes/${folder}/bicep-shoulder-bracket-exal__1__1.stl" scale="0.001 0.001 0.001"/>
            </geometry>
          </collision>
        </link>
        
        <link name="${prefix}_bicep-shoulder-bracket-exal__2__1">
          <inertial>
            <origin xyz="0.011983042446582756 -0.004518260205939313 ${sign*-0.0054648499906134115}" rpy="0 0 0"/>
            <mass value="0.0119000299936683"/>
            <inertia ixx="1.06039831340363e-06" iyy="1.5252300019405e-06" izz="2.34706806988363e-06" ixy="${sign*-1.68859995043294e-07}" iyz="${sign*6.776263578034403e-21}" ixz="1.355252715606881e-20"/>
          </inertial>
          <visual>
            <origin xyz="-0.065252 0.006662 ${sign*-0.0561}" rpy="0 0 0"/>
            <geometry>
              <mesh filename="package://hyperspawn_dropbear_description/meshes/${folder}/bicep-shoulder-bracket-exal__2__1.stl" scale="0.001 0.001 0.001"/>
            </geometry>
            <material name="opaque245245245"/>
          </visual>
          <collision>
            <origin xyz="-0.065252 0.006662 ${sign*-0.0561}" rpy="0 0 0"/>
            <geometry>
              <mesh filename="package://hyperspawn_dropbear_description/meshes/${folder}/bicep-shoulder-bracket-exal__2__1.stl" scale="0.001 0.001 0.001"/>
            </geometry>
          </collision>
        </link>
        
        <link name="${prefix}_2020_100mm__8__1">
          <inertial>
            <origin xyz="-0.02187147869637933 0.034952359549973555 ${sign*-0.009999999999981746}" rpy="0 0 0"/>
            <mass value="0.019591747444562"/>
            <inertia ixx="1.5641987506042e-05" iyy="3.0794735109847e-06" izz="1.71247911413717e-05" ixy="${sign*4.56360033803824e-06}" iyz="${sign*-7.738493006115288e-18}" ixz="2.507217523872729e-18"/>
          </inertial>
          <visual>
            <origin xyz="-0.097956 0.010231 ${sign*-0.0761}" rpy="0 0 0"/>
            <geometry>
              <mesh filename="package://hyperspawn_dropbear_description/meshes/${folder}/2020_100mm__8__1.stl" scale="0.001 0.001 0.001"/>
            </geometry>
            <material name="opaque727161"/>
          </visual>
          <collision>
            <origin xyz="-0.097956 0.010231 ${sign*-0.0761}" rpy="0 0 0"/>
            <geometry>
              <mesh filename="package://hyperspawn_dropbear_description/meshes/${folder}/2020_100mm__8__1.stl" scale="0.001 0.001 0.001"/>
            </geometry>
          </collision>
        </link>
        
        <link name="${prefix}_yaw-waist-adapter-motor-exal_MIR1__5__1">
          <inertial>
            <origin xyz="0.008570545572160838 -0.049788080074744674 ${sign*1.457167719820518e-15}" rpy="0 0 0"/>
            <mass value="0.0374132377219994"/>
            <inertia ixx="1.41382993236902e-05" iyy="1.30292783846948e-05" izz="7.05842073186832e-06" ixy="${sign*4.02875438314004e-07}" iyz="${sign*-6.776263578034403e-21}" ixz="5.421010862427522e-20"/>
          </inertial>
          <visual>
            <origin xyz="-0.060634 -0.072274 ${sign*-0.0661}" rpy="0 0 0"/>
            <geometry>
              <mesh filename="package://hyperspawn_dropbear_description/meshes/${folder}/yaw-waist-adapter-motor-exal_MIR1__5__1.stl" scale="0.001 0.001 0.001"/>
            </geometry>
            <material name="opaque245245245"/>
          </visual>
          <collision>
            <origin xyz="-0.060634 -0.072274 ${sign*-0.0661}" rpy="0 0 0"/>
            <geometry>
              <mesh filename="package://hyperspawn_dropbear_description/meshes/${folder}/yaw-waist-adapter-motor-exal_MIR1__5__1.stl" scale="0.001 0.001 0.001"/>
            </geometry>
          </collision>
        </link>
        
        <link name="${prefix}_bicep-shoulder-bracket-exal_1">
          <inertial>
            <origin xyz="-0.014231130165287431 -0.020921360581575885 ${sign*-0.007214849990613441}" rpy="0 0 0"/>
            <mass value="0.0119000299936683"/>
            <inertia ixx="1.06039831340366e-06" iyy="1.5252300019405e-06" izz="2.34706806988368e-06" ixy="${sign*-1.68859995043294e-07}" iyz="${sign*6.776263578034403e-21}" ixz="1.355252715606881e-20"/>
          </inertial>
          <visual>
            <origin xyz="-0.070144 -0.075364 ${sign*-0.05785}" rpy="0 0 0"/>
            <geometry>
              <mesh filename="package://hyperspawn_dropbear_description/meshes/${folder}/bicep-shoulder-bracket-exal_1.stl" scale="0.001 0.001 0.001"/>
            </geometry>
            <material name="opaque245245245"/>
          </visual>
          <collision>
            <origin xyz="-0.070144 -0.075364 ${sign*-0.05785}" rpy="0 0 0"/>
            <geometry>
              <mesh filename="package://hyperspawn_dropbear_description/meshes/${folder}/bicep-shoulder-bracket-exal_1.stl" scale="0.001 0.001 0.001"/>
            </geometry>
          </collision>
        </link>
        
        <link name="${prefix}_shoulder-front_1">
          <inertial>
            <origin xyz="-0.007463364992977992 -0.010559925065031256 ${sign*0.010000000000000855}" rpy="0 0 0"/>
            <mass value="0.0285901454621081"/>
            <inertia ixx="5.24738535853905e-06" iyy="5.75381404316444e-06" izz="5.10534101569437e-06" ixy="${sign*-1.12882167821954e-07}" iyz="${sign*-4.118613002729310e-17}" ixz="-1.249543003789544e-16"/>
          </inertial>
          <visual>
            <origin xyz="-0.04393 -0.058961 ${sign*-0.0561}" rpy="0 0 0"/>
            <geometry>
              <mesh filename="package://hyperspawn_dropbear_description/meshes/${folder}/shoulder-front_1.stl" scale="0.001 0.001 0.001"/>
            </geometry>
            <material name="opaque191191191"/>
          </visual>
          <collision>
            <origin xyz="-0.04393 -0.058961 ${sign*-0.0561}" rpy="0 0 0"/>
            <geometry>
              <mesh filename="package://hyperspawn_dropbear_description/meshes/${folder}/shoulder-front_1.stl" scale="0.001 0.001 0.001"/>
            </geometry>
          </collision>
        </link>
        
        <link name="${prefix}_bicep-shoulder-bracket-exal__3__1">
          <inertial>
            <origin xyz="0.011982869834713333 -0.00451836058157562 ${sign*0.0055351500093866746}" rpy="0 0 0"/>
            <mass value="0.0119000299936683"/>
            <inertia ixx="1.06039831340366e-06" iyy="1.52523000194053e-06" izz="2.3470680698837e-06" ixy="${sign*-1.688599950433e-07}" iyz="${sign*6.776263578034403e-21}" ixz="1.355252715606881e-20"/>
          </inertial>
          <visual>
            <origin xyz="-0.04393 -0.058961 ${sign*-0.0761}" rpy="0 0 0"/>
            <geometry>
              <mesh filename="package://hyperspawn_dropbear_description/meshes/${folder}/bicep-shoulder-bracket-exal__3__1.stl" scale="0.001 0.001 0.001"/>
            </geometry>
            <material name="opaque245245245"/>
          </visual>
          <collision>
            <origin xyz="-0.04393 -0.058961 ${sign*-0.0761}" rpy="0 0 0"/>
            <geometry>
              <mesh filename="package://hyperspawn_dropbear_description/meshes/${folder}/bicep-shoulder-bracket-exal__3__1.stl" scale="0.001 0.001 0.001"/>
            </geometry>
          </collision>
        </link>
        
        <link name="${prefix}_shoulder-cap_1">
          <inertial>
            <origin xyz="-0.034857061179216664 -0.006155365677712535 ${sign*-0.02572256391671531}" rpy="0 0 0"/>
            <mass value="0.046227678179176"/>
            <inertia ixx="1.76465028282704e-05" iyy="3.51734867524788e-05" izz="2.25355319862365e-05" ixy="${sign*-6.39975511036637e-06}" iyz="${sign*-1.32005071311637e-06}" ixz="-4.02230543927391e-06"/>
          </inertial>
          <visual>
            <origin xyz="-0.024494 -0.060532 ${sign*-0.0811}" rpy="0 0 0"/>
            <geometry>
              <mesh filename="package://hyperspawn_dropbear_description/meshes/${folder}/shoulder-cap_1.stl" scale="0.001 0.001 0.001"/>
            </geometry>
            <material name="opaque245245245"/>
          </visual>
          <collision>
            <origin xyz="-0.024494 -0.060532 ${sign*-0.0811}" rpy="0 0 0"/>
            <geometry>
              <mesh filename="package://hyperspawn_dropbear_description/meshes/${folder}/shoulder-cap_1.stl" scale="0.001 0.001 0.001"/>
            </geometry>
          </collision>
        </link>
        
        <link name="${prefix}_shoulder-front-bearing-adapter_1">
          <inertial>
            <origin xyz="0.002386025471724852 -0.007343142980721001 ${sign*-2.1516816106625924e-13}" rpy="0 0 0"/>
            <mass value="0.0517827683159966"/>
            <inertia ixx="2.00897215647814e-05" iyy="3.34357881365482e-05" izz="1.85144321830305e-05" ixy="${sign*-4.84824247298993e-06}" iyz="${sign*-2.439454888092385e-19}" ixz="6.776263578034403e-21"/>
          </inertial>
          <visual>
            <origin xyz="0.015451 -0.047553 ${sign*-0.0521}" rpy="0 0 0"/>
            <geometry>
              <mesh filename="package://hyperspawn_dropbear_description/meshes/${folder}/shoulder-front-bearing-adapter_1.stl" scale="0.001 0.001 0.001"/>
            </geometry>
            <material name="opaque22122113"/>
          </visual>
          <collision>
            <origin xyz="0.015451 -0.047553 ${sign*-0.0521}" rpy="0 0 0"/>
            <geometry>
              <mesh filename="package://hyperspawn_dropbear_description/meshes/${folder}/shoulder-front-bearing-adapter_1.stl" scale="0.001 0.001 0.001"/>
            </geometry>
          </collision>
        </link>
        
        <link name="${prefix}_skateboard-bearing__7__1">
          <inertial>
            <origin xyz="0.0010817588048354296 -0.0033289225564277353 ${sign*6.462885782099193e-14}" rpy="0 0 0"/>
            <mass value="0.00230907060038848"/>
            <inertia ixx="9.51660210389439e-08" iyy="1.51519688193447e-07" izz="8.85143732875385e-08" ixy="${sign*-2.04716678984035e-08}" iyz="${sign*0}" ixz="0"/>
          </inertial>
          <visual>
            <origin xyz="0.014268 -0.043912 ${sign*-0.0521}" rpy="0 0 0"/>
            <geometry>
              <mesh filename="package://hyperspawn_dropbear_description/meshes/${folder}/skateboard-bearing__7__1.stl" scale="0.001 0.001 0.001"/>
            </geometry>
            <material name="opaque191191191"/>
          </visual>
          <collision>
            <origin xyz="0.014268 -0.043912 ${sign*-0.0521}" rpy="0 0 0"/>
            <geometry>
              <mesh filename="package://hyperspawn_dropbear_description/meshes/${folder}/skateboard-bearing__7__1.stl" scale="0.001 0.001 0.001"/>
            </geometry>
          </collision>
        </link>
        
        <link name="${prefix}_shoulder-ex-al-interface__1__1">
          <inertial>
            <origin xyz="0.005086309920670065 0.011115745348658862 ${sign*-0.015588000000003085}" rpy="0 0 0"/>
            <mass value="0.027893677646265"/>
            <inertia ixx="8.62918953092065e-06" iyy="6.55151618232706e-06" izz="3.84451183650918e-06" ixy="${sign*7.54759023527542e-07}" iyz="${sign*-7.428817760599116e-17}" ixz="2.390665790330537e-17"/>
          </inertial>
          <visual>
            <origin xyz="-0.088376 -0.019252 ${sign*-0.081688}" rpy="0 0 0"/>
            <geometry>
              <mesh filename="package://hyperspawn_dropbear_description/meshes/${folder}/shoulder-ex-al-interface__1__1.stl" scale="0.001 0.001 0.001"/>
            </geometry>
            <material name="opaque22122113"/>
          </visual>
          <collision>
            <origin xyz="-0.088376 -0.019252 ${sign*-0.081688}" rpy="0 0 0"/>
            <geometry>
              <mesh filename="package://hyperspawn_dropbear_description/meshes/${folder}/shoulder-ex-al-interface__1__1.stl" scale="0.001 0.001 0.001"/>
            </geometry>
          </collision>
        </link>
        
        <link name="${prefix}_RMD-X8-Pro_MIR8_MIR1__3__1">
          <inertial>
            <origin xyz="0.020811032738451224 0.006758332348657088 ${sign*-0.0004617607034976129}" rpy="0 0 0"/>
            <mass value="0.0658409996798309"/>
            <inertia ixx="9.09774292415633e-05" iyy="6.7319850864883e-05" izz="6.35281702686577e-05" ixy="${sign*8.5891712197628e-06}" iyz="${sign*2.3364395504617e-07}" ixz="7.13422628698264e-07"/>
          </inertial>
          <visual>
            <origin xyz="-0.101763 -0.033065 ${sign*-0.0661}" rpy="0 0 0"/>
            <geometry>
              <mesh filename="package://hyperspawn_dropbear_description/meshes/${folder}/RMD-X8-Pro_MIR8_MIR1__3__1.stl" scale="0.001 0.001 0.001"/>
            </geometry>
            <material name="opaque13110895"/>
          </visual>
          <collision>
            <origin xyz="-0.101763 -0.033065 ${sign*-0.0661}" rpy="0 0 0"/>
            <geometry>
              <mesh filename="package://hyperspawn_dropbear_description/meshes/${folder}/RMD-X8-Pro_MIR8_MIR1__3__1.stl" scale="0.001 0.001 0.001"/>
            </geometry>
          </collision>
        </link>
        
        <link name="${prefix}_bicep-rotational-cuff-second-motor-bracket_1">
          <inertial>
            <origin xyz="0.02579329779689743 -0.027346829280827607 ${sign*0.011692978353793584}" rpy="0 0 0"/>
            <mass value="0.0320781339241104"/>
            <inertia ixx="3.41151769728197e-05" iyy="7.91300090191788e-06" izz="3.80752971458179e-05" ixy="${sign*9.51849738174703e-06}" iyz="${sign*2.75547767213661e-08}" ixz="8.48427415083269e-08"/>
          </inertial>
          <visual>
            <origin xyz="-0.126928 -0.076969 ${sign*-0.041413}" rpy="0 0 0"/>
            <geometry>
              <mesh filename="package://hyperspawn_dropbear_description/meshes/${folder}/bicep-rotational-cuff-second-motor-bracket_1.stl" scale="0.001 0.001 0.001"/>
            </geometry>
            <material name="opaque245245245"/>
          </visual>
          <collision>
            <origin xyz="-0.126928 -0.076969 ${sign*-0.041413}" rpy="0 0 0"/>
            <geometry>
              <mesh filename="package://hyperspawn_dropbear_description/meshes/${folder}/bicep-rotational-cuff-second-motor-bracket_1.stl" scale="0.001 0.001 0.001"/>
            </geometry>
          </collision>
        </link>
        
        <link name="${prefix}_arm-cuff-bicep-bracket_1">
          <inertial>
            <origin xyz="0.026747737541988198 -0.027037140279867637 ${sign*0.010976523865579235}" rpy="0 0 0"/>
            <mass value="0.0396071482598914"/>
            <inertia ixx="1.72909087565665e-05" iyy="6.95389552897961e-06" izz="2.08996292553588e-05" ixy="${sign*3.75496291676885e-06}" iyz="${sign*-6.15614302756809e-08}" ixz="-1.88151444691781e-07"/>
          </inertial>
          <visual>
            <origin xyz="-0.126928 -0.076969 ${sign*-0.090787}" rpy="0 0 0"/>
            <geometry>
              <mesh filename="package://hyperspawn_dropbear_description/meshes/${folder}/arm-cuff-bicep-bracket_1.stl" scale="0.001 0.001 0.001"/>
            </geometry>
            <material name="opaque245245245"/>
          </visual>
          <collision>
            <origin xyz="-0.126928 -0.076969 ${sign*-0.090787}" rpy="0 0 0"/>
            <geometry>
              <mesh filename="package://hyperspawn_dropbear_description/meshes/${folder}/arm-cuff-bicep-bracket_1.stl" scale="0.001 0.001 0.001"/>
            </geometry>
          </collision>
        </link>
        
        <link name="${prefix}_RMD-X8-Pro_MIR8_MIR1__2__1">
          <inertial>
            <origin xyz="0.04008391366910127 0.012538887934983922 ${sign*-0.01561908096714007}" rpy="0 0 0"/>
            <mass value="0.0658409996798309"/>
            <inertia ixx="6.44336317909464e-05" iyy="6.36248988822963e-05" izz="9.37669197018588e-05" ixy="${sign*2.95951172273197e-07}" iyz="${sign*7.12726270180649e-07}" ixz="-2.35787126190521e-07"/>
          </inertial>
          <visual>
            <origin xyz="-0.158351 -0.051451 ${sign*-0.0941}" rpy="0 0 0"/>
            <geometry>
              <mesh filename="package://hyperspawn_dropbear_description/meshes/${folder}/RMD-X8-Pro_MIR8_MIR1__2__1.stl" scale="0.001 0.001 0.001"/>
            </geometry>
            <material name="opaque13110895"/>
          </visual>
          <collision>
            <origin xyz="-0.158351 -0.051451 ${sign*-0.0941}" rpy="0 0 0"/>
            <geometry>
              <mesh filename="package://hyperspawn_dropbear_description/meshes/${folder}/RMD-X8-Pro_MIR8_MIR1__2__1.stl" scale="0.001 0.001 0.001"/>
            </geometry>
          </collision>
        </link>
        
        <link name="${prefix}_elbow-hangar_1">
          <inertial>
            <origin xyz="0.009097755696947596 0.008492177017401778 ${sign*0.0053454030039173095}" rpy="0 0 0"/>
            <mass value="0.0204020833630401"/>
            <inertia ixx="6.6421250278737e-06" iyy="4.11811022617411e-06" izz="1.03527066425164e-05" ixy="${sign*-8.109713974891e-08}" iyz="${sign*1.26245664383887e-08}" ixz="3.49860892958232e-09"/>
          </inertial>
          <visual>
            <origin xyz="-0.23824 -0.077409 ${sign*-0.0941}" rpy="0 0 0"/>
            <geometry>
              <mesh filename="package://hyperspawn_dropbear_description/meshes/${folder}/elbow-hangar_1.stl" scale="0.001 0.001 0.001"/>
            </geometry>
            <material name="opaque245245245"/>
          </visual>
          <collision>
            <origin xyz="-0.23824 -0.077409 ${sign*-0.0941}" rpy="0 0 0"/>
            <geometry>
              <mesh filename="package://hyperspawn_dropbear_description/meshes/${folder}/elbow-hangar_1.stl" scale="0.001 0.001 0.001"/>
            </geometry>
          </collision>
        </link>
        
        <link name="${prefix}_elbow-hangar1_1">
          <inertial>
            <origin xyz="0.009239632983326695 0.008659896006840764 ${sign*-0.005352531151966877}" rpy="0 0 0"/>
            <mass value="0.0206552999135536"/>
            <inertia ixx="6.71852816144279e-06" iyy="4.18187895299157e-06" izz="1.04933666904246e-05" ixy="${sign*-9.19621016773212e-08}" iyz="${sign*-1.0640147190554e-08}" ixz="-1.82105253153462e-09"/>
          </inertial>
          <visual>
            <origin xyz="-0.238212 -0.077493 ${sign*-0.0591}" rpy="0 0 0"/>
            <geometry>
              <mesh filename="package://hyperspawn_dropbear_description/meshes/${folder}/elbow-hangar1_1.stl" scale="0.001 0.001 0.001"/>
            </geometry>
            <material name="opaque191191191"/>
          </visual>
          <collision>
            <origin xyz="-0.238212 -0.077493 ${sign*-0.0591}" rpy="0 0 0"/>
            <geometry>
              <mesh filename="package://hyperspawn_dropbear_description/meshes/${folder}/elbow-hangar1_1.stl" scale="0.001 0.001 0.001"/>
            </geometry>
          </collision>
        </link>
        
        <link name="${prefix}_power-mount-arm_1">
          <inertial>
            <origin xyz="0.0199725006095543 0.007084375363081735 ${sign*-0.007564191049157856}" rpy="0 0 0"/>
            <mass value="0.00920761435653255"/>
            <inertia ixx="6.93163292977354e-07" iyy="2.31947497968756e-06" izz="2.76652425160314e-06" ixy="${sign*-8.26146077881631e-07}" iyz="${sign*9.47310549299942e-08}" ixz="1.55844231409296e-07"/>
          </inertial>
          <visual>
            <origin xyz="-0.198384 -0.02243 ${sign*-0.0591}" rpy="0 0 0"/>
            <geometry>
              <mesh filename="package://hyperspawn_dropbear_description/meshes/${folder}/power-mount-arm_1.stl" scale="0.001 0.001 0.001"/>
            </geometry>
            <material name="opaque191191191"/>
          </visual>
          <collision>
            <origin xyz="-0.198384 -0.02243 ${sign*-0.0591}" rpy="0 0 0"/>
            <geometry>
              <mesh filename="package://hyperspawn_dropbear_description/meshes/${folder}/power-mount-arm_1.stl" scale="0.001 0.001 0.001"/>
            </geometry>
          </collision>
        </link>
        
        <link name="${prefix}_fan-mount_1">
          <inertial>
            <origin xyz="0.007614354119151734 0.000836188010462844 ${sign*0.01662058044961192}" rpy="0 0 0"/>
            <mass value="0.00644067140035774"/>
            <inertia ixx="1.48605155910032e-06" iyy="3.68013686438944e-06" izz="2.83932016880128e-06" ixy="${sign*-7.97050051407598e-07}" iyz="${sign*-2.97112695746051e-08}" ixz="9.68054293153044e-09"/>
          </inertial>
          <visual>
            <origin xyz="-0.206393 -0.015511 ${sign*-0.0526}" rpy="0 0 0"/>
            <geometry>
              <mesh filename="package://hyperspawn_dropbear_description/meshes/${folder}/fan-mount_1.stl" scale="0.001 0.001 0.001"/>
            </geometry>
            <material name="opaque191191191"/>
          </visual>
          <collision>
            <origin xyz="-0.206393 -0.015511 ${sign*-0.0526}" rpy="0 0 0"/>
            <geometry>
              <mesh filename="package://hyperspawn_dropbear_description/meshes/${folder}/fan-mount_1.stl" scale="0.001 0.001 0.001"/>
            </geometry>
          </collision>
        </link>
        
        <link name="${prefix}_bicep-motor-mate_1">
          <inertial>
            <origin xyz="0.0036413059649408053 0.01829349155933041 ${sign*-0.005357773320266546}" rpy="0 0 0"/>
            <mass value="0.0234002691640453"/>
            <inertia ixx="1.32060288590759e-05" iyy="2.54192298376364e-06" izz="1.53523578903067e-05" ixy="${sign*-2.21008972083536e-06}" iyz="${sign*-8.0372672143551e-08}" ixz="-1.59965060578119e-08"/>
          </inertial>
          <visual>
            <origin xyz="-0.198295 -0.06443 ${sign*-0.0571}" rpy="0 0 0"/>
            <geometry>
              <mesh filename="package://hyperspawn_dropbear_description/meshes/${folder}/bicep-motor-mate_1.stl" scale="0.001 0.001 0.001"/>
            </geometry>
            <material name="opaque22122113"/>
          </visual>
          <collision>
            <origin xyz="-0.198295 -0.06443 ${sign*-0.0571}" rpy="0 0 0"/>
            <geometry>
              <mesh filename="package://hyperspawn_dropbear_description/meshes/${folder}/bicep-motor-mate_1.stl" scale="0.001 0.001 0.001"/>
            </geometry>
          </collision>
        </link>
        
        <link name="${prefix}_6mm-bearing_1">
          <inertial>
            <origin xyz="-3.5326930772350273e-07 -2.214747430728803e-07 ${sign*0.0025000000000666572}" rpy="0 0 0"/>
            <mass value="0.000742201264410583"/>
            <inertia ixx="1.36534108097759e-08" iyy="1.36534107510715e-08" izz="2.42143162924741e-08" ixy="${sign*2.874491009802194e-17}" iyz="${sign*0}" ixz="-5.082197683525802e-21"/>
          </inertial>
          <visual>
            <origin xyz="-0.210008 -0.123276 ${sign*-0.0596}" rpy="0 0 0"/>
            <geometry>
              <mesh filename="package://hyperspawn_dropbear_description/meshes/${folder}/6mm-bearing_1.stl" scale="0.001 0.001 0.001"/>
            </geometry>
            <material name="opaque244244244"/>
          </visual>
          <collision>
            <origin xyz="-0.210008 -0.123276 ${sign*-0.0596}" rpy="0 0 0"/>
            <geometry>
              <mesh filename="package://hyperspawn_dropbear_description/meshes/${folder}/6mm-bearing_1.stl" scale="0.001 0.001 0.001"/>
            </geometry>
          </collision>
        </link>
        
        <link name="${prefix}_bicep_1">
          <inertial>
            <origin xyz="0.025241062458964486 0.003467924642948428 ${sign*-0.0024679893349933285}" rpy="0 0 0"/>
            <mass value="0.00452110353215657"/>
            <inertia ixx="1.78635876769165e-07" iyy="1.59943917593539e-06" izz="1.72883353989758e-06" ixy="${sign*-2.22997923500127e-07}" iyz="${sign*-1.13161037261654e-08}" ixz="-8.64330203756723e-08"/>
          </inertial>
          <visual>
            <origin xyz="-0.210008 -0.123276 ${sign*-0.0646}" rpy="0 0 0"/>
            <geometry>
              <mesh filename="package://hyperspawn_dropbear_description/meshes/${folder}/bicep_1.stl" scale="0.001 0.001 0.001"/>
            </geometry>
            <material name="opaque245245245"/>
          </visual>
          <collision>
            <origin xyz="-0.210008 -0.123276 ${sign*-0.0646}" rpy="0 0 0"/>
            <geometry>
              <mesh filename="package://hyperspawn_dropbear_description/meshes/${folder}/bicep_1.stl" scale="0.001 0.001 0.001"/>
            </geometry>
          </collision>
        </link>
        
        <link name="${prefix}_6mm-bearing__9__1">
          <inertial>
            <origin xyz="2.865579871724755e-07 1.0929456925601322e-07 ${sign*0.00250000000008746}" rpy="0 0 0"/>
            <mass value="0.000742201264410583"/>
            <inertia ixx="1.36534108186749e-08" iyy="1.36534107421742e-08" izz="2.42143162924538e-08" ixy="${sign*1.498231877103406e-17}" iyz="${sign*0}" ixz="-5.082197683525802e-21"/>
          </inertial>
          <visual>
            <origin xyz="-0.259138 -0.132559 ${sign*-0.0596}" rpy="0 0 0"/>
            <geometry>
              <mesh filename="package://hyperspawn_dropbear_description/meshes/${folder}/6mm-bearing__9__1.stl" scale="0.001 0.001 0.001"/>
            </geometry>
            <material name="opaque244244244"/>
          </visual>
          <collision>
            <origin xyz="-0.259138 -0.132559 ${sign*-0.0596}" rpy="0 0 0"/>
            <geometry>
              <mesh filename="package://hyperspawn_dropbear_description/meshes/${folder}/6mm-bearing__9__1.stl" scale="0.001 0.001 0.001"/>
            </geometry>
          </collision>
        </link>
        
        <link name="${prefix}_straight-tendon_1">
          <inertial>
            <origin xyz="0.016982130987867106 -0.03009616821723135 ${sign*0.011870768566949505}" rpy="0 0 0"/>
            <mass value="0.0328967120048395"/>
            <inertia ixx="1.2026531689926e-05" iyy="1.84226655396526e-05" izz="2.75121662277849e-05" ixy="${sign*1.05830445656609e-05}" iyz="${sign*1.27172353512099e-07}" ixz="-7.15971958302562e-08"/>
          </inertial>
          <visual>
            <origin xyz="-0.259138 -0.132559 ${sign*-0.0646}" rpy="0 0 0"/>
            <geometry>
              <mesh filename="package://hyperspawn_dropbear_description/meshes/${folder}/straight-tendon_1.stl" scale="0.001 0.001 0.001"/>
            </geometry>
            <material name="opaque191191191"/>
          </visual>
          <collision>
            <origin xyz="-0.259138 -0.132559 ${sign*-0.0646}" rpy="0 0 0"/>
            <geometry>
              <mesh filename="package://hyperspawn_dropbear_description/meshes/${folder}/straight-tendon_1.stl" scale="0.001 0.001 0.001"/>
            </geometry>
          </collision>
        </link>
        
        <link name="${prefix}_6mm-bearing__1__1">
          <inertial>
            <origin xyz="2.7684984724163364e-07 3.2034255134649747e-07 ${sign*-0.002499999999997768}" rpy="0 0 0"/>
            <mass value="0.000742201264410583"/>
            <inertia ixx="1.36534107809988e-08" iyy="1.36534107798503e-08" izz="2.42143162924809e-08" ixy="${sign*-4.107093354646651e-17}" iyz="${sign*0}" ixz="-3.388131789017201e-21"/>
          </inertial>
          <visual>
            <origin xyz="-0.248202 -0.110095 ${sign*-0.0936}" rpy="0 0 0"/>
            <geometry>
              <mesh filename="package://hyperspawn_dropbear_description/meshes/${folder}/6mm-bearing__1__1.stl" scale="0.001 0.001 0.001"/>
            </geometry>
            <material name="opaque244244244"/>
          </visual>
          <collision>
            <origin xyz="-0.248202 -0.110095 ${sign*-0.0936}" rpy="0 0 0"/>
            <geometry>
              <mesh filename="package://hyperspawn_dropbear_description/meshes/${folder}/6mm-bearing__1__1.stl" scale="0.001 0.001 0.001"/>
            </geometry>
          </collision>
        </link>
        
        <link name="${prefix}_6mm-bearing__5__1">
          <inertial>
            <origin xyz="-2.579352154363779e-07 -2.4019200871305824e-07 ${sign*0.0025000000000022435}" rpy="0 0 0"/>
            <mass value="0.000742201264410583"/>
            <inertia ixx="1.36534107810039e-08" iyy="1.3653410779857e-08" izz="2.42143162924809e-08" ixy="${sign*-4.107770981004455e-17}" iyz="${sign*-1.694065894508601e-21}" ixz="-3.388131789017201e-21"/>
          </inertial>
          <visual>
            <origin xyz="-0.248175 -0.11018 ${sign*-0.0596}" rpy="0 0 0"/>
            <geometry>
              <mesh filename="package://hyperspawn_dropbear_description/meshes/${folder}/6mm-bearing__5__1.stl" scale="0.001 0.001 0.001"/>
            </geometry>
            <material name="opaque244244244"/>
          </visual>
          <collision>
            <origin xyz="-0.248175 -0.11018 ${sign*-0.0596}" rpy="0 0 0"/>
            <geometry>
              <mesh filename="package://hyperspawn_dropbear_description/meshes/${folder}/6mm-bearing__5__1.stl" scale="0.001 0.001 0.001"/>
            </geometry>
          </collision>
        </link>
        
        <link name="${prefix}_6mm-bearing__2__1">
          <inertial>
            <origin xyz="-3.244389845113993e-07 -4.2206160963398354e-07 ${sign*-0.002499999999997643}" rpy="0 0 0"/>
            <mass value="0.000742201264410583"/>
            <inertia ixx="1.36534107810005e-08" iyy="1.36534107798638e-08" izz="2.42143162924741e-08" ixy="${sign*-4.107770981004455e-17}" iyz="${sign*0}" ixz="0"/>
          </inertial>
          <visual>
            <origin xyz="-0.269544 -0.088998 ${sign*-0.0936}" rpy="0 0 0"/>
            <geometry>
              <mesh filename="package://hyperspawn_dropbear_description/meshes/${folder}/6mm-bearing__2__1.stl" scale="0.001 0.001 0.001"/>
            </geometry>
            <material name="opaque244244244"/>
          </visual>
          <collision>
            <origin xyz="-0.269544 -0.088998 ${sign*-0.0936}" rpy="0 0 0"/>
            <geometry>
              <mesh filename="package://hyperspawn_dropbear_description/meshes/${folder}/6mm-bearing__2__1.stl" scale="0.001 0.001 0.001"/>
            </geometry>
          </collision>
        </link>
        
        <link name="${prefix}_elbow-bridge-rear__1__1">
          <inertial>
            <origin xyz="0.00037731086861581 -0.0006154201679538229 ${sign*-0.012000384647695192}" rpy="0 0 0"/>
            <mass value="0.0028705367164362"/>
            <inertia ixx="1.64013592546732e-07" iyy="1.69029719705434e-07" izz="8.44000480725439e-08" ixy="${sign*-4.94462821241156e-09}" iyz="${sign*6.270768206453371e-13}" ixz="-4.202376294171195e-13"/>
          </inertial>
          <visual>
            <origin xyz="-0.269544 -0.088998 ${sign*-0.0886}" rpy="0 0 0"/>
            <geometry>
              <mesh filename="package://hyperspawn_dropbear_description/meshes/${folder}/elbow-bridge-rear__1__1.stl" scale="0.001 0.001 0.001"/>
            </geometry>
            <material name="opaque22122113"/>
          </visual>
          <collision>
            <origin xyz="-0.269544 -0.088998 ${sign*-0.0886}" rpy="0 0 0"/>
            <geometry>
              <mesh filename="package://hyperspawn_dropbear_description/meshes/${folder}/elbow-bridge-rear__1__1.stl" scale="0.001 0.001 0.001"/>
            </geometry>
          </collision>
        </link>
        
        <link name="${prefix}_6mm-bearing__6__1">
          <inertial>
            <origin xyz="1.4077586790728347e-07 1.740391428195487e-08 ${sign*0.0025000000000023684}" rpy="0 0 0"/>
            <mass value="0.000742201264410583"/>
            <inertia ixx="1.36534107810005e-08" iyy="1.36534107798503e-08" izz="2.42143162924673e-08" ixy="${sign*-4.107432167825553e-17}" iyz="${sign*8.470329472543003e-22}" ixz="5.082197683525802e-21"/>
          </inertial>
          <visual>
            <origin xyz="-0.269516 -0.089082 ${sign*-0.0596}" rpy="0 0 0"/>
            <geometry>
              <mesh filename="package://hyperspawn_dropbear_description/meshes/${folder}/6mm-bearing__6__1.stl" scale="0.001 0.001 0.001"/>
            </geometry>
            <material name="opaque244244244"/>
          </visual>
          <collision>
            <origin xyz="-0.269516 -0.089082 ${sign*-0.0596}" rpy="0 0 0"/>
            <geometry>
              <mesh filename="package://hyperspawn_dropbear_description/meshes/${folder}/6mm-bearing__6__1.stl" scale="0.001 0.001 0.001"/>
            </geometry>
          </collision>
        </link>
        
        <link name="${prefix}_elbow-rear-hanger__1__1">
          <inertial>
            <origin xyz="0.02934379676100346 0.008989918119322815 ${sign*-0.004053673616636819}" rpy="0 0 0"/>
            <mass value="0.00878773207629285"/>
            <inertia ixx="1.1522637629092e-06" iyy="2.77857409078255e-06" izz="3.8398800936702e-06" ixy="${sign*-1.32357239278618e-06}" iyz="${sign*2.66633484505264e-09}" ixz="-1.49038211958406e-09"/>
          </inertial>
          <visual>
            <origin xyz="-0.269544 -0.088998 ${sign*-0.0936}" rpy="0 0 0"/>
            <geometry>
              <mesh filename="package://hyperspawn_dropbear_description/meshes/${folder}/elbow-rear-hanger__1__1.stl" scale="0.001 0.001 0.001"/>
            </geometry>
            <material name="opaque808080"/>
          </visual>
          <collision>
            <origin xyz="-0.269544 -0.088998 ${sign*-0.0936}" rpy="0 0 0"/>
            <geometry>
              <mesh filename="package://hyperspawn_dropbear_description/meshes/${folder}/elbow-rear-hanger__1__1.stl" scale="0.001 0.001 0.001"/>
            </geometry>
          </collision>
        </link>
        
        <link name="${prefix}_elbow-rear-hanger_1">
          <inertial>
            <origin xyz="0.029350657033763494 0.008974172754350793 ${sign*0.004053673616641912}" rpy="0 0 0"/>
            <mass value="0.00878773207629285"/>
            <inertia ixx="1.15065037986482e-06" iyy="2.78018747382691e-06" izz="3.83988009366998e-06" ixy="${sign*-1.32257983291486e-06}" iyz="${sign*-2.66652047281092e-09}" ixz="1.4900499778806e-09"/>
          </inertial>
          <visual>
            <origin xyz="-0.269516 -0.089082 ${sign*-0.0596}" rpy="0 0 0"/>
            <geometry>
              <mesh filename="package://hyperspawn_dropbear_description/meshes/${folder}/elbow-rear-hanger_1.stl" scale="0.001 0.001 0.001"/>
            </geometry>
            <material name="opaque808080"/>
          </visual>
          <collision>
            <origin xyz="-0.269516 -0.089082 ${sign*-0.0596}" rpy="0 0 0"/>
            <geometry>
              <mesh filename="package://hyperspawn_dropbear_description/meshes/${folder}/elbow-rear-hanger_1.stl" scale="0.001 0.001 0.001"/>
            </geometry>
          </collision>
        </link>
        
        <link name="${prefix}_6mm-bearing__7__1">
          <inertial>
            <origin xyz="-3.636756962244192e-08 -4.999536466626653e-07 ${sign*0.002500000000108589}" rpy="0 0 0"/>
            <mass value="0.000742201264410583"/>
            <inertia ixx="1.3653410811426e-08" iyy="1.36534107494316e-08" izz="2.42143162924673e-08" ixy="${sign*-2.694920024984282e-17}" iyz="${sign*4.235164736271502e-22}" ixz="0"/>
          </inertial>
          <visual>
            <origin xyz="-0.30936 -0.080341 ${sign*-0.0596}" rpy="0 0 0"/>
            <geometry>
              <mesh filename="package://hyperspawn_dropbear_description/meshes/${folder}/6mm-bearing__7__1.stl" scale="0.001 0.001 0.001"/>
            </geometry>
            <material name="opaque244244244"/>
          </visual>
          <collision>
            <origin xyz="-0.30936 -0.080341 ${sign*-0.0596}" rpy="0 0 0"/>
            <geometry>
              <mesh filename="package://hyperspawn_dropbear_description/meshes/${folder}/6mm-bearing__7__1.stl" scale="0.001 0.001 0.001"/>
            </geometry>
          </collision>
        </link>
        
        <link name="${prefix}_6mm-bearing__4__1">
          <inertial>
            <origin xyz="-3.636765966152922e-08 -4.999536816763239e-07 ${sign*-0.00249999999989145}" rpy="0 0 0"/>
            <mass value="0.000742201264410583"/>
            <inertia ixx="1.36534107494215e-08" iyy="1.36534108114209e-08" izz="2.42143162924673e-08" ixy="${sign*2.695258838163184e-17}" iyz="${sign*0}" ixz="-3.388131789017201e-21"/>
          </inertial>
          <visual>
            <origin xyz="-0.30936 -0.080341 ${sign*-0.0936}" rpy="0 0 0"/>
            <geometry>
              <mesh filename="package://hyperspawn_dropbear_description/meshes/${folder}/6mm-bearing__4__1.stl" scale="0.001 0.001 0.001"/>
            </geometry>
            <material name="opaque244244244"/>
          </visual>
          <collision>
            <origin xyz="-0.30936 -0.080341 ${sign*-0.0936}" rpy="0 0 0"/>
            <geometry>
              <mesh filename="package://hyperspawn_dropbear_description/meshes/${folder}/6mm-bearing__4__1.stl" scale="0.001 0.001 0.001"/>
            </geometry>
          </collision>
        </link>
        
        <link name="${prefix}_forearm-elbow-motor-bracket-inner2_1">
          <inertial>
            <origin xyz="0.01210452779343929 0.018768296075041158 ${sign*0.006000210735618364}" rpy="0 0 0"/>
            <mass value="0.0192069448509669"/>
            <inertia ixx="6.21792569103477e-06" iyy="2.28550673511642e-06" izz="8.12040624796964e-06" ixy="${sign*3.33924211184293e-07}" iyz="${sign*-2.97249573777891e-09}" ixz="-1.98666460270516e-08"/>
          </inertial>
          <visual>
            <origin xyz="-0.30936 -0.080341 ${sign*-0.0936}" rpy="0 0 0"/>
            <geometry>
              <mesh filename="package://hyperspawn_dropbear_description/meshes/${folder}/forearm-elbow-motor-bracket-inner2_1.stl" scale="0.001 0.001 0.001"/>
            </geometry>
            <material name="opaque22122113"/>
          </visual>
          <collision>
            <origin xyz="-0.30936 -0.080341 ${sign*-0.0936}" rpy="0 0 0"/>
            <geometry>
              <mesh filename="package://hyperspawn_dropbear_description/meshes/${folder}/forearm-elbow-motor-bracket-inner2_1.stl" scale="0.001 0.001 0.001"/>
            </geometry>
          </collision>
        </link>
        
        <link name="${prefix}_6mm-bearing__3__1">
          <inertial>
            <origin xyz="-3.3812888700079924e-07 -4.80847968137299e-07 ${sign*-0.0024999999998957523}" rpy="0 0 0"/>
            <mass value="0.000742201264410583"/>
            <inertia ixx="1.36534108134029e-08" iyy="1.36534107474529e-08" izz="2.42143162924538e-08" ixy="${sign*-2.448264030743830e-17}" iyz="${sign*1.694065894508601e-21}" ixz="3.388131789017201e-21"/>
          </inertial>
          <visual>
            <origin xyz="-0.32192 -0.118318 ${sign*-0.0936}" rpy="0 0 0"/>
            <geometry>
              <mesh filename="package://hyperspawn_dropbear_description/meshes/${folder}/6mm-bearing__3__1.stl" scale="0.001 0.001 0.001"/>
            </geometry>
            <material name="opaque244244244"/>
          </visual>
          <collision>
            <origin xyz="-0.32192 -0.118318 ${sign*-0.0936}" rpy="0 0 0"/>
            <geometry>
              <mesh filename="package://hyperspawn_dropbear_description/meshes/${folder}/6mm-bearing__3__1.stl" scale="0.001 0.001 0.001"/>
            </geometry>
          </collision>
        </link>
        
        <link name="${prefix}_elbow-bridge-rear_1">
          <inertial>
            <origin xyz="0.00017362146100646791 0.0006999255750166633 ${sign*-0.012000384647593357}" rpy="0 0 0"/>
            <mass value="0.0028705367164362"/>
            <inertia ixx="1.61621552749476e-07" iyy="1.71421759502684e-07" izz="8.44000480725439e-08" ixy="${sign*2.59397725035102e-09}" iyz="${sign*-7.392586265093492e-13}" ixz="-1.527144160911806e-13"/>
          </inertial>
          <visual>
            <origin xyz="-0.32192 -0.118318 ${sign*-0.0886}" rpy="0 0 0"/>
            <geometry>
              <mesh filename="package://hyperspawn_dropbear_description/meshes/${folder}/elbow-bridge-rear_1.stl" scale="0.001 0.001 0.001"/>
            </geometry>
            <material name="opaque22122113"/>
          </visual>
          <collision>
            <origin xyz="-0.32192 -0.118318 ${sign*-0.0886}" rpy="0 0 0"/>
            <geometry>
              <mesh filename="package://hyperspawn_dropbear_description/meshes/${folder}/elbow-bridge-rear_1.stl" scale="0.001 0.001 0.001"/>
            </geometry>
          </collision>
        </link>
        
        <link name="${prefix}_second-forearm-motor-strap_1">
          <inertial>
            <origin xyz="0.014708936033833275 -0.02081565891948628 ${sign*0.002509257258482181}" rpy="0 0 0"/>
            <mass value="0.0131449054705419"/>
            <inertia ixx="3.43138676629572e-06" iyy="1.58695113719942e-06" izz="4.77340242408691e-06" ixy="${sign*5.10902521250233e-07}" iyz="${sign*6.16354740128598e-08}" ixz="1.402440507787e-07"/>
          </inertial>
          <visual>
            <origin xyz="-0.318828 -0.127828 ${sign*-0.1051}" rpy="0 0 0"/>
            <geometry>
              <mesh filename="package://hyperspawn_dropbear_description/meshes/${folder}/second-forearm-motor-strap_1.stl" scale="0.001 0.001 0.001"/>
            </geometry>
            <material name="opaque245245245"/>
          </visual>
          <collision>
            <origin xyz="-0.318828 -0.127828 ${sign*-0.1051}" rpy="0 0 0"/>
            <geometry>
              <mesh filename="package://hyperspawn_dropbear_description/meshes/${folder}/second-forearm-motor-strap_1.stl" scale="0.001 0.001 0.001"/>
            </geometry>
          </collision>
        </link>
        
        <link name="${prefix}_RMD-X8-Pro_MIR8_MIR1__4__1">
          <inertial>
            <origin xyz="0.018861805978547308 -0.007520690639387845 ${sign*-0.04040576070339569}" rpy="0 0 0"/>
            <mass value="0.0658409996798309"/>
            <inertia ixx="9.09838616472696e-05" iyy="6.73134184591643e-05" izz="6.35281702686431e-05" ixy="${sign*8.58030568945184e-06}" iyz="${sign*-2.33376660648183e-07}" ixz="-7.13510111442729e-07"/>
          </inertial>
          <visual>
            <origin xyz="-0.345523 -0.125898 ${sign*-0.106044}" rpy="0 0 0"/>
            <geometry>
              <mesh filename="package://hyperspawn_dropbear_description/meshes/${folder}/RMD-X8-Pro_MIR8_MIR1__4__1.stl" scale="0.001 0.001 0.001"/>
            </geometry>
            <material name="opaque13110895"/>
          </visual>
          <collision>
            <origin xyz="-0.345523 -0.125898 ${sign*-0.106044}" rpy="0 0 0"/>
            <geometry>
              <mesh filename="package://hyperspawn_dropbear_description/meshes/${folder}/RMD-X8-Pro_MIR8_MIR1__4__1.stl" scale="0.001 0.001 0.001"/>
            </geometry>
          </collision>
        </link>
        
        <link name="${prefix}_fore-arm-bicep-motor-attatch_1">
          <inertial>
            <origin xyz="-0.009651244394266734 -0.03898859615972326 ${sign*0.00035796122303864003}" rpy="0 0 0"/>
            <mass value="0.0209546718492168"/>
            <inertia ixx="1.04514300674843e-05" iyy="2.58698928522509e-06" izz="1.24986679126875e-05" ixy="${sign*2.78916445132994e-06}" iyz="${sign*2.66278334695827e-08}" ixz="2.02287240043527e-08"/>
          </inertial>
          <visual>
            <origin xyz="-0.339041 -0.145873 ${sign*-0.041413}" rpy="0 0 0"/>
            <geometry>
              <mesh filename="package://hyperspawn_dropbear_description/meshes/${folder}/fore-arm-bicep-motor-attatch_1.stl" scale="0.001 0.001 0.001"/>
            </geometry>
            <material name="opaque245245245"/>
          </visual>
          <collision>
            <origin xyz="-0.339041 -0.145873 ${sign*-0.041413}" rpy="0 0 0"/>
            <geometry>
              <mesh filename="package://hyperspawn_dropbear_description/meshes/${folder}/fore-arm-bicep-motor-attatch_1.stl" scale="0.001 0.001 0.001"/>
            </geometry>
          </collision>
        </link>
        
        <link name="${prefix}_forearm-elbow-motor-bracket-inner_1">
          <inertial>
            <origin xyz="0.002543710639871688 -0.02871711147828905 ${sign*0.005494237705661112}" rpy="0 0 0"/>
            <mass value="0.0194601610964149"/>
            <inertia ixx="6.31121950777307e-06" iyy="2.30522493752019e-06" izz="8.23398459688131e-06" ixy="${sign*3.01641193478706e-07}" iyz="${sign*2.98435509831841e-09}" ixz="1.92473633802413e-08"/>
          </inertial>
          <visual>
            <origin xyz="-0.318828 -0.127827 ${sign*-0.0481}" rpy="0 0 0"/>
            <geometry>
              <mesh filename="package://hyperspawn_dropbear_description/meshes/${folder}/forearm-elbow-motor-bracket-inner_1.stl" scale="0.001 0.001 0.001"/>
            </geometry>
            <material name="opaque22122113"/>
          </visual>
          <collision>
            <origin xyz="-0.318828 -0.127827 ${sign*-0.0481}" rpy="0 0 0"/>
            <geometry>
              <mesh filename="package://hyperspawn_dropbear_description/meshes/${folder}/forearm-elbow-motor-bracket-inner_1.stl" scale="0.001 0.001 0.001"/>
            </geometry>
          </collision>
        </link>
        
        <link name="${prefix}_6mm-bearing__8__1">
          <inertial>
            <origin xyz="1.8166938153818535e-07 -6.957382656103128e-08 ${sign*0.0025000000001725795}" rpy="0 0 0"/>
            <mass value="0.000742201264410583"/>
            <inertia ixx="1.36534107474767e-08" iyy="1.36534108133724e-08" izz="2.42143162924809e-08" ixy="${sign*2.453346228427356e-17}" iyz="${sign*-8.470329472543003e-22}" ixz="0"/>
          </inertial>
          <visual>
            <origin xyz="-0.321914 -0.118315 ${sign*-0.0596}" rpy="0 0 0"/>
            <geometry>
              <mesh filename="package://hyperspawn_dropbear_description/meshes/${folder}/6mm-bearing__8__1.stl" scale="0.001 0.001 0.001"/>
            </geometry>
            <material name="opaque244244244"/>
          </visual>
          <collision>
            <origin xyz="-0.321914 -0.118315 ${sign*-0.0596}" rpy="0 0 0"/>
            <geometry>
              <mesh filename="package://hyperspawn_dropbear_description/meshes/${folder}/6mm-bearing__8__1.stl" scale="0.001 0.001 0.001"/>
            </geometry>
          </collision>
        </link>
        
        <link name="${prefix}_shoulder-ex-al-interface_1">
          <inertial>
            <origin xyz="0.008777069212284438 0.002847989226232972 ${sign*1.0648426584936033e-13}" rpy="0 0 0"/>
            <mass value="0.027893677646265"/>
            <inertia ixx="8.62975476795724e-06" iyy="6.55095094528966e-06" izz="3.84451183650918e-06" ixy="${sign*7.53980428245355e-07}" iyz="${sign*7.418653365232064e-17}" ixz="-2.428612866367530e-17"/>
          </inertial>
          <visual>
            <origin xyz="-0.384723 -0.124974 ${sign*-0.0661}" rpy="0 0 0"/>
            <geometry>
              <mesh filename="package://hyperspawn_dropbear_description/meshes/${folder}/shoulder-ex-al-interface_1.stl" scale="0.001 0.001 0.001"/>
            </geometry>
            <material name="opaque22122113"/>
          </visual>
          <collision>
            <origin xyz="-0.384723 -0.124974 ${sign*-0.0661}" rpy="0 0 0"/>
            <geometry>
              <mesh filename="package://hyperspawn_dropbear_description/meshes/${folder}/shoulder-ex-al-interface_1.stl" scale="0.001 0.001 0.001"/>
            </geometry>
          </collision>
        </link>
        
        <link name="${prefix}_shoulder-roll-al-mot_MIR1__3__1">
          <inertial>
            <origin xyz="0.015475495394150607 -0.0044405328981518 ${sign*-0.0010043671574723606}" rpy="0 0 0"/>
            <mass value="0.0139822805624322"/>
            <inertia ixx="1.88229880822098e-06" iyy="1.27958507925314e-06" izz="2.5168338003939e-06" ixy="${sign*2.18564846424479e-07}" iyz="${sign*4.61044448857295e-09}" ixz="1.41533491789534e-08"/>
          </inertial>
          <visual>
            <origin xyz="-0.39859 -0.138936 ${sign*-0.050512}" rpy="0 0 0"/>
            <geometry>
              <mesh filename="package://hyperspawn_dropbear_description/meshes/${folder}/shoulder-roll-al-mot_MIR1__3__1.stl" scale="0.001 0.001 0.001"/>
            </geometry>
            <material name="opaque245245245"/>
          </visual>
          <collision>
            <origin xyz="-0.39859 -0.138936 ${sign*-0.050512}" rpy="0 0 0"/>
            <geometry>
              <mesh filename="package://hyperspawn_dropbear_description/meshes/${folder}/shoulder-roll-al-mot_MIR1__3__1.stl" scale="0.001 0.001 0.001"/>
            </geometry>
          </collision>
        </link>
        
        <link name="${prefix}_shoulder-roll-al-mot_MIR1_1">
          <inertial>
            <origin xyz="0.015475426626878619 -0.004440320984141877 ${sign*0.0010033671576757525}" rpy="0 0 0"/>
            <mass value="0.0139822805624322"/>
            <inertia ixx="1.88226180650956e-06" iyy="1.2796220809643e-06" izz="2.51683380039346e-06" ixy="${sign*2.18615855241441e-07}" iyz="${sign*-4.57859064090195e-09}" ixz="-1.4163685929235e-08"/>
          </inertial>
          <visual>
            <origin xyz="-0.39859 -0.138936 ${sign*-0.081689}" rpy="0 0 0"/>
            <geometry>
              <mesh filename="package://hyperspawn_dropbear_description/meshes/${folder}/shoulder-roll-al-mot_MIR1_1.stl" scale="0.001 0.001 0.001"/>
            </geometry>
            <material name="opaque245245245"/>
          </visual>
          <collision>
            <origin xyz="-0.39859 -0.138936 ${sign*-0.081689}" rpy="0 0 0"/>
            <geometry>
              <mesh filename="package://hyperspawn_dropbear_description/meshes/${folder}/shoulder-roll-al-mot_MIR1_1.stl" scale="0.001 0.001 0.001"/>
            </geometry>
          </collision>
        </link>
        
        <link name="${prefix}_2020_100mm__10__1">
          <inertial>
            <origin xyz="0.04755886079292104 0.015433290864262622 ${sign*1.0068335054569388e-13}" rpy="0 0 0"/>
            <mass value="0.019591747444562"/>
            <inertia ixx="3.07605584273351e-06" iyy="1.56454051740999e-05" izz="1.71247911416065e-05" ixy="${sign*-4.5588926132704e-06}" iyz="${sign*1.084202172485504e-19}" ixz="2.168404344971009e-19"/>
          </inertial>
          <visual>
            <origin xyz="-0.401368 -0.130375 ${sign*-0.0661}" rpy="0 0 0"/>
            <geometry>
              <mesh filename="package://hyperspawn_dropbear_description/meshes/${folder}/2020_100mm__10__1.stl" scale="0.001 0.001 0.001"/>
            </geometry>
            <material name="opaque727161"/>
          </visual>
          <collision>
            <origin xyz="-0.401368 -0.130375 ${sign*-0.0661}" rpy="0 0 0"/>
            <geometry>
              <mesh filename="package://hyperspawn_dropbear_description/meshes/${folder}/2020_100mm__10__1.stl" scale="0.001 0.001 0.001"/>
            </geometry>
          </collision>
        </link>
        
        <link name="${prefix}_top-bracket-servo-strap_1">
          <inertial>
            <origin xyz="0.03411014913308452 0.011047031874247631 ${sign*1.204420641340298e-05}" rpy="0 0 0"/>
            <mass value="0.0175777981223999"/>
            <inertia ixx="9.29479846030251e-06" iyy="5.47481508958057e-06" izz="5.02507725581381e-06" ixy="${sign*1.3855824304073e-06}" iyz="${sign*-4.310728897861764e-11}" ixz="-2.134664385360086e-11"/>
          </inertial>
          <visual>
            <origin xyz="-0.401368 -0.130375 ${sign*-0.0661}" rpy="0 0 0"/>
            <geometry>
              <mesh filename="package://hyperspawn_dropbear_description/meshes/${folder}/top-bracket-servo-strap_1.stl" scale="0.001 0.001 0.001"/>
            </geometry>
            <material name="opaque191191191"/>
          </visual>
          <collision>
            <origin xyz="-0.401368 -0.130375 ${sign*-0.0661}" rpy="0 0 0"/>
            <geometry>
              <mesh filename="package://hyperspawn_dropbear_description/meshes/${folder}/top-bracket-servo-strap_1.stl" scale="0.001 0.001 0.001"/>
            </geometry>
          </collision>
        </link>
        
        <link name="${prefix}_MG995_1">
          <inertial>
            <origin xyz="0.02542053581561582 -0.001276948059540317 ${sign*-0.004850007599141448}" rpy="0 0 0"/>
            <mass value="0.032566461385389"/>
            <inertia ixx="5.38895774384847e-06" iyy="5.59171425588111e-06" izz="8.86947697656577e-06" ixy="${sign*4.14631043579167e-08}" iyz="${sign*5.365051773068702e-12}" ixz="4.980090775527635e-13"/>
          </inertial>
          <visual>
            <origin xyz="-0.430497 -0.160434 ${sign*-0.05095}" rpy="0 0 0"/>
            <geometry>
              <mesh filename="package://hyperspawn_dropbear_description/meshes/${folder}/MG995_1.stl" scale="0.001 0.001 0.001"/>
            </geometry>
            <material name="opaque636363"/>
          </visual>
          <collision>
            <origin xyz="-0.430497 -0.160434 ${sign*-0.05095}" rpy="0 0 0"/>
            <geometry>
              <mesh filename="package://hyperspawn_dropbear_description/meshes/${folder}/MG995_1.stl" scale="0.001 0.001 0.001"/>
            </geometry>
          </collision>
        </link>
        
        <link name="${prefix}_MG995__4__1">
          <inertial>
            <origin xyz="0.02412079550410856 0.002727982934733808 ${sign*0.009060775705328955}" rpy="0 0 0"/>
            <mass value="0.032566461385389"/>
            <inertia ixx="5.76005376702008e-06" iyy="8.54204411183338e-06" izz="5.54805109744851e-06" ixy="${sign*-1.00902296761973e-06}" iyz="${sign*-2.8737861608219e-08}" ixz="-8.85428860033805e-08"/>
          </inertial>
          <visual>
            <origin xyz="-0.441223 -0.127381 ${sign*-0.0465}" rpy="0 0 0"/>
            <geometry>
              <mesh filename="package://hyperspawn_dropbear_description/meshes/${folder}/MG995__4__1.stl" scale="0.001 0.001 0.001"/>
            </geometry>
            <material name="opaque636363"/>
          </visual>
          <collision>
            <origin xyz="-0.441223 -0.127381 ${sign*-0.0465}" rpy="0 0 0"/>
            <geometry>
              <mesh filename="package://hyperspawn_dropbear_description/meshes/${folder}/MG995__4__1.stl" scale="0.001 0.001 0.001"/>
            </geometry>
          </collision>
        </link>
        
        <link name="${prefix}_MG995__3__1">
          <inertial>
            <origin xyz="0.019827623818259865 0.015959817195865075 ${sign*0.004850007599342093}" rpy="0 0 0"/>
            <mass value="0.032566461385389"/>
            <inertia ixx="5.49827845502016e-06" iyy="5.48239354471181e-06" izz="8.86947697656664e-06" ixy="${sign*-1.09241279847103e-07}" iyz="${sign*4.050359277574939e-12}" ixz="-3.553362248540082e-12"/>
          </inertial>
          <visual>
            <origin xyz="-0.442596 -0.123148 ${sign*-0.08125}" rpy="0 0 0"/>
            <geometry>
              <mesh filename="package://hyperspawn_dropbear_description/meshes/${folder}/MG995__3__1.stl" scale="0.001 0.001 0.001"/>
            </geometry>
            <material name="opaque636363"/>
          </visual>
          <collision>
            <origin xyz="-0.442596 -0.123148 ${sign*-0.08125}" rpy="0 0 0"/>
            <geometry>
              <mesh filename="package://hyperspawn_dropbear_description/meshes/${folder}/MG995__3__1.stl" scale="0.001 0.001 0.001"/>
            </geometry>
          </collision>
        </link>
        
        <link name="${prefix}_MG995__5__1">
          <inertial>
            <origin xyz="0.021127364129767012 0.011954886201590936 ${sign*-0.009060775705128143}" rpy="0 0 0"/>
            <mass value="0.032566461385389"/>
            <inertia ixx="5.76005626801851e-06" iyy="8.54204161083831e-06" izz="5.54805109744851e-06" ixy="${sign*-1.0090264153783e-06}" iyz="${sign*2.87284461969787e-08}" ixz="8.85459413568768e-08"/>
          </inertial>
          <visual>
            <origin xyz="-0.43187 -0.156201 ${sign*-0.0857}" rpy="0 0 0"/>
            <geometry>
              <mesh filename="package://hyperspawn_dropbear_description/meshes/${folder}/MG995__5__1.stl" scale="0.001 0.001 0.001"/>
            </geometry>
            <material name="opaque636363"/>
          </visual>
          <collision>
            <origin xyz="-0.43187 -0.156201 ${sign*-0.0857}" rpy="0 0 0"/>
            <geometry>
              <mesh filename="package://hyperspawn_dropbear_description/meshes/${folder}/MG995__5__1.stl" scale="0.001 0.001 0.001"/>
            </geometry>
          </collision>
        </link>
        
        <link name="${prefix}_2020_100mm__11__1">
          <inertial>
            <origin xyz="0.09510320422272961 0.030861694308185278 ${sign*9.919842725025774e-14}" rpy="0 0 0"/>
            <mass value="0.019591747444562"/>
            <inertia ixx="3.07605584273991e-06" iyy="1.56454051740713e-05" izz="1.71247911415996e-05" ixy="${sign*-4.55889261327929e-06}" iyz="${sign*1.084202172485504e-19}" ixz="3.252606517456513e-19"/>
          </inertial>
          <visual>
            <origin xyz="-0.401368 -0.130375 ${sign*-0.0661}" rpy="0 0 0"/>
            <geometry>
              <mesh filename="package://hyperspawn_dropbear_description/meshes/${folder}/2020_100mm__11__1.stl" scale="0.001 0.001 0.001"/>
            </geometry>
            <material name="opaque727161"/>
          </visual>
          <collision>
            <origin xyz="-0.401368 -0.130375 ${sign*-0.0661}" rpy="0 0 0"/>
            <geometry>
              <mesh filename="package://hyperspawn_dropbear_description/meshes/${folder}/2020_100mm__11__1.stl" scale="0.001 0.001 0.001"/>
            </geometry>
          </collision>
        </link>
        
        <link name="${prefix}_top-bracket-servo-strap__1__1">
          <inertial>
            <origin xyz="-0.009381861774768185 -0.0030667560010047834 ${sign*-1.2044206214339992e-05}" rpy="0 0 0"/>
            <mass value="0.0175777981223999"/>
            <inertia ixx="9.29487224457558e-06" iyy="5.47474130530891e-06" izz="5.02507725581424e-06" ixy="${sign*1.38548071488285e-06}" iyz="${sign*2.235920584965634e-11}" ixz="-4.259088502885089e-11"/>
          </inertial>
          <visual>
            <origin xyz="-0.54403 -0.17667 ${sign*-0.0661}" rpy="0 0 0"/>
            <geometry>
              <mesh filename="package://hyperspawn_dropbear_description/meshes/${folder}/top-bracket-servo-strap__1__1.stl" scale="0.001 0.001 0.001"/>
            </geometry>
            <material name="opaque191191191"/>
          </visual>
          <collision>
            <origin xyz="-0.54403 -0.17667 ${sign*-0.0661}" rpy="0 0 0"/>
            <geometry>
              <mesh filename="package://hyperspawn_dropbear_description/meshes/${folder}/top-bracket-servo-strap__1__1.stl" scale="0.001 0.001 0.001"/>
            </geometry>
          </collision>
        </link>
        
        <link name="${prefix}_MG995__2__1">
          <inertial>
            <origin xyz="-0.024121471517170034 -0.0027287589888995434 ${sign*0.009060775705327699}" rpy="0 0 0"/>
            <mass value="0.032566461385389"/>
            <inertia ixx="5.76005376701997e-06" iyy="8.54204411183251e-06" izz="5.54805109744851e-06" ixy="${sign*-1.00902296761886e-06}" iyz="${sign*2.87378616086798e-08}" ixz="8.85428860044647e-08"/>
          </inertial>
          <visual>
            <origin xyz="-0.528891 -0.187685 ${sign*-0.0465}" rpy="0 0 0"/>
            <geometry>
              <mesh filename="package://hyperspawn_dropbear_description/meshes/${folder}/MG995__2__1.stl" scale="0.001 0.001 0.001"/>
            </geometry>
            <material name="opaque636363"/>
          </visual>
          <collision>
            <origin xyz="-0.528891 -0.187685 ${sign*-0.0465}" rpy="0 0 0"/>
            <geometry>
              <mesh filename="package://hyperspawn_dropbear_description/meshes/${folder}/MG995__2__1.stl" scale="0.001 0.001 0.001"/>
            </geometry>
          </collision>
        </link>
        
        <link name="${prefix}_MG995__6__1">
          <inertial>
            <origin xyz="-0.025421211828677737 0.0012771720053743607 ${sign*-0.00485000759914328}" rpy="0 0 0"/>
            <mass value="0.032566461385389"/>
            <inertia ixx="5.38895774384988e-06" iyy="5.59171425588978e-06" izz="8.86947697657445e-06" ixy="${sign*4.14631043548809e-08}" iyz="${sign*-5.365051935699028e-12}" ixz="-4.980085354516772e-13"/>
          </inertial>
          <visual>
            <origin xyz="-0.539617 -0.154631 ${sign*-0.05095}" rpy="0 0 0"/>
            <geometry>
              <mesh filename="package://hyperspawn_dropbear_description/meshes/${folder}/MG995__6__1.stl" scale="0.001 0.001 0.001"/>
            </geometry>
            <material name="opaque636363"/>
          </visual>
          <collision>
            <origin xyz="-0.539617 -0.154631 ${sign*-0.05095}" rpy="0 0 0"/>
            <geometry>
              <mesh filename="package://hyperspawn_dropbear_description/meshes/${folder}/MG995__6__1.stl" scale="0.001 0.001 0.001"/>
            </geometry>
          </collision>
        </link>
        
        <link name="${prefix}_MG995__1__1">
          <inertial>
            <origin xyz="-0.02112704014282696 -0.011954662255756893 ${sign*-0.009060775705130197}" rpy="0 0 0"/>
            <mass value="0.032566461385389"/>
            <inertia ixx="5.76005626801829e-06" iyy="8.54204161083311e-06" izz="5.54805109744157e-06" ixy="${sign*-1.00902641537743e-06}" iyz="${sign*-2.87284461971413e-08}" ixz="-8.85459413568768e-08"/>
          </inertial>
          <visual>
            <origin xyz="-0.538243 -0.158864 ${sign*-0.0857}" rpy="0 0 0"/>
            <geometry>
              <mesh filename="package://hyperspawn_dropbear_description/meshes/${folder}/MG995__1__1.stl" scale="0.001 0.001 0.001"/>
            </geometry>
            <material name="opaque636363"/>
          </visual>
          <collision>
            <origin xyz="-0.538243 -0.158864 ${sign*-0.0857}" rpy="0 0 0"/>
            <geometry>
              <mesh filename="package://hyperspawn_dropbear_description/meshes/${folder}/MG995__1__1.stl" scale="0.001 0.001 0.001"/>
            </geometry>
          </collision>
        </link>
        
        <link name="${prefix}_MG995__7__1">
          <inertial>
            <origin xyz="-0.019827299831319145 -0.0159595932500311 ${sign*0.004850007599340733}" rpy="0 0 0"/>
            <mass value="0.032566461385389"/>
            <inertia ixx="5.49827845501886e-06" iyy="5.48239354471181e-06" izz="8.86947697656577e-06" ixy="${sign*-1.09241279844935e-07}" iyz="${sign*-4.050359331785047e-12}" ixz="3.553362899061385e-12"/>
          </inertial>
          <visual>
            <origin xyz="-0.527517 -0.191917 ${sign*-0.08125}" rpy="0 0 0"/>
            <geometry>
              <mesh filename="package://hyperspawn_dropbear_description/meshes/${folder}/MG995__7__1.stl" scale="0.001 0.001 0.001"/>
            </geometry>
            <material name="opaque636363"/>
          </visual>
          <collision>
            <origin xyz="-0.527517 -0.191917 ${sign*-0.08125}" rpy="0 0 0"/>
            <geometry>
              <mesh filename="package://hyperspawn_dropbear_description/meshes/${folder}/MG995__7__1.stl" scale="0.001 0.001 0.001"/>
            </geometry>
          </collision>
        </link>
        
        <link name="${prefix}_multiplex-stack-flat_1">
          <inertial>
            <origin xyz="-0.010298214415190743 0.0316942752130374 ${sign*0.007502408653395604}" rpy="0 0 0"/>
            <mass value="0.0196851916219767"/>
            <inertia ixx="2.20267292244485e-05" iyy="4.33346762103762e-06" izz="2.61301709215887e-05" ixy="${sign*6.4274160590935e-06}" iyz="${sign*-2.08940472779795e-08}" ixz="6.79501824664246e-09"/>
          </inertial>
          <visual>
            <origin xyz="-0.077235 0.01118 ${sign*-0.0871}" rpy="0 0 0"/>
            <geometry>
              <mesh filename="package://hyperspawn_dropbear_description/meshes/${folder}/multiplex-stack-flat_1.stl" scale="0.001 0.001 0.001"/>
            </geometry>
            <material name="opaque191191191"/>
          </visual>
          <collision>
            <origin xyz="-0.077235 0.01118 ${sign*-0.0871}" rpy="0 0 0"/>
            <geometry>
              <mesh filename="package://hyperspawn_dropbear_description/meshes/${folder}/multiplex-stack-flat_1.stl" scale="0.001 0.001 0.001"/>
            </geometry>
          </collision>
        </link>
        
        <joint name="${prefix}_torso_connection" type="fixed">
            <xacro:insert_block name="origin"/>
            <parent link="${parent}"/>
            <child link="${prefix}_2020_100mm__9__1"/>
          </joint>
        
        <joint name="${prefix}_Rigid 2" type="fixed">
          <origin xyz="0.0 0.0 ${sign*0.0}" rpy="0 0 0"/>
          <parent link="${prefix}_2020_100mm__9__1"/>
          <child link="${prefix}_shoulder-roll-al-mot_MIR1__1__1"/>
        </joint>
        
        <joint name="${prefix}_Rigid 3" type="fixed">
          <origin xyz="0.0 0.0 ${sign*0.0}" rpy="0 0 0"/>
          <parent link="${prefix}_2020_100mm__9__1"/>
          <child link="${prefix}_shoulder-roll-al-mot_MIR1__2__1"/>
        </joint>
        
        <joint name="${prefix}_Rigid 4" type="fixed">
          <origin xyz="0.0 0.0 ${sign*0.1}" rpy="0 0 0"/>
          <parent link="${prefix}_2020_100mm__9__1"/>
          <child link="${prefix}_yaw-cap_1"/>
        </joint>
        
        <joint name="${prefix}_Rigid 5" type="fixed">
          <origin xyz="0.0 0.0 ${sign*0.0}" rpy="0 0 0"/>
          <parent link="${prefix}_2020_100mm__9__1"/>
          <child link="${prefix}_yaw-waist-adapter-motor-exal_MIR1_1"/>
        </joint>
        
        <joint name="${prefix}_Rigid 6" type="fixed">
          <origin xyz="-0.021006 0.014204 ${sign*0.059}" rpy="0 0 0"/>
          <parent link="${prefix}_yaw-waist-adapter-motor-exal_MIR1_1"/>
          <child link="${prefix}_front-bearing-adapter-shoulder_1"/>
        </joint>
        
        <joint name="${prefix}_Rigid 7" type="fixed">
          <origin xyz="-0.011735 -0.014328 ${sign*0.059}" rpy="0 0 0"/>
          <parent link="${prefix}_yaw-waist-adapter-motor-exal_MIR1_1"/>
          <child link="${prefix}_shoulder-ex-al-interface__2__1"/>
        </joint>
        
        <joint name="${prefix}_pitch" type="revolute">
          <origin xyz="0.020078 -0.011351 ${sign*-0.009}" rpy="0 0 0"/>
          <parent link="${prefix}_shoulder-ex-al-interface__2__1"/>
          <child link="${prefix}_RMD-X8-Pro_MIR8_MIR1__1__1"/>
          <axis xyz="0.309017 -0.951057 -0.0"/>
          <limit upper="${PI}" lower="${-PI}" velocity="10.0" effort="100.0"/>
        </joint>
        
        <joint name="${prefix}_Rigid 9" type="fixed">
          <origin xyz="0.051533 -0.022685 ${sign*0.0}" rpy="0 0 0"/>
          <parent link="${prefix}_RMD-X8-Pro_MIR8_MIR1__1__1"/>
          <child link="${prefix}_shoulder-motor-bicep-rotor-bracket_1"/>
        </joint>
        
        <joint name="${prefix}_Rigid 10" type="fixed">
          <origin xyz="0.017119 0.005562 ${sign*-0.0015}" rpy="0 0 0"/>
          <parent link="${prefix}_shoulder-motor-bicep-rotor-bracket_1"/>
          <child link="${prefix}_bicep-rear-motor-adapter_1"/>
        </joint>
        
        <joint name="${prefix}_Rigid 11" type="fixed">
          <origin xyz="-0.011743 0.03614 ${sign*0.0255}" rpy="0 0 0"/>
          <parent link="${prefix}_bicep-rear-motor-adapter_1"/>
          <child link="${prefix}_bicep-shoulder-bracket-exal__1__1"/>
        </joint>
        
        <joint name="${prefix}_Rigid 12" type="fixed">
          <origin xyz="-0.011743 0.03614 ${sign*0.0055}" rpy="0 0 0"/>
          <parent link="${prefix}_bicep-rear-motor-adapter_1"/>
          <child link="${prefix}_bicep-shoulder-bracket-exal__2__1"/>
        </joint>
        
        <joint name="${prefix}_Rigid 13" type="fixed">
          <origin xyz="0.032704 -0.003569 ${sign*0.0}" rpy="0 0 0"/>
          <parent link="${prefix}_bicep-shoulder-bracket-exal__1__1"/>
          <child link="${prefix}_2020_100mm__8__1"/>
        </joint>
        
        <joint name="${prefix}_Rigid 14" type="fixed">
          <origin xyz="-0.037322 0.082505 ${sign*-0.01}" rpy="0 0 0"/>
          <parent link="${prefix}_2020_100mm__8__1"/>
          <child link="${prefix}_yaw-waist-adapter-motor-exal_MIR1__5__1"/>
        </joint>
        
        <joint name="${prefix}_Rigid 15" type="fixed">
          <origin xyz="-0.027812 0.085595 ${sign*-0.01825}" rpy="0 0 0"/>
          <parent link="${prefix}_2020_100mm__8__1"/>
          <child link="${prefix}_bicep-shoulder-bracket-exal_1"/>
        </joint>
        
        <joint name="${prefix}_Rigid 16" type="fixed">
          <origin xyz="-0.026214 -0.016403 ${sign*-0.00175}" rpy="0 0 0"/>
          <parent link="${prefix}_bicep-shoulder-bracket-exal_1"/>
          <child link="${prefix}_shoulder-front_1"/>
        </joint>
        
        <joint name="${prefix}_Rigid 17" type="fixed">
          <origin xyz="0.0 0.0 ${sign*0.02}" rpy="0 0 0"/>
          <parent link="${prefix}_shoulder-front_1"/>
          <child link="${prefix}_bicep-shoulder-bracket-exal__3__1"/>
        </joint>
        
        <joint name="${prefix}_Rigid 18" type="fixed">
          <origin xyz="-0.019436 0.001571 ${sign*0.025}" rpy="0 0 0"/>
          <parent link="${prefix}_shoulder-front_1"/>
          <child link="${prefix}_shoulder-cap_1"/>
        </joint>
        
        <joint name="${prefix}_Rigid 19" type="fixed">
          <origin xyz="-0.039945 -0.012979 ${sign*-0.029}" rpy="0 0 0"/>
          <parent link="${prefix}_shoulder-cap_1"/>
          <child link="${prefix}_shoulder-front-bearing-adapter_1"/>
        </joint>
        
        <joint name="${prefix}_Revolute 20" type="fixed">
          <origin xyz="0.001183 -0.003641 ${sign*0.0}" rpy="0 0 0"/>
          <parent link="${prefix}_shoulder-front-bearing-adapter_1"/>
          <child link="${prefix}_skateboard-bearing__7__1"/>
        </joint>
        
        <joint name="${prefix}_Rigid 21" type="fixed">
          <origin xyz="0.027742 -0.053022 ${sign*0.015588}" rpy="0 0 0"/>
          <parent link="${prefix}_yaw-waist-adapter-motor-exal_MIR1__5__1"/>
          <child link="${prefix}_shoulder-ex-al-interface__1__1"/>
        </joint>
        
        <joint name="${prefix}_roll" type="revolute">
          <origin xyz="0.013387 0.013813 ${sign*-0.015588}" rpy="0 0 0"/>
          <parent link="${prefix}_shoulder-ex-al-interface__1__1"/>
          <child link="${prefix}_RMD-X8-Pro_MIR8_MIR1__3__1"/>
          <axis xyz="0.951057 0.309017 0.0"/>
          <limit upper="${PI}" lower="${-PI}" velocity="10.0" effort="100.0"/>
        </joint>
        
        <joint name="${prefix}_Rigid 23" type="fixed">
          <origin xyz="0.025165 0.043904 ${sign*-0.024687}" rpy="0 0 0"/>
          <parent link="${prefix}_RMD-X8-Pro_MIR8_MIR1__3__1"/>
          <child link="${prefix}_bicep-rotational-cuff-second-motor-bracket_1"/>
        </joint>
        
        <joint name="${prefix}_Rigid 24" type="fixed">
          <origin xyz="0.025165 0.043904 ${sign*0.024687}" rpy="0 0 0"/>
          <parent link="${prefix}_RMD-X8-Pro_MIR8_MIR1__3__1"/>
          <child link="${prefix}_arm-cuff-bicep-bracket_1"/>
        </joint>
        
        <joint name="${prefix}_Rigid 25" type="fixed">
          <origin xyz="0.031423 -0.025518 ${sign*0.003313}" rpy="0 0 0"/>
          <parent link="${prefix}_arm-cuff-bicep-bracket_1"/>
          <child link="${prefix}_RMD-X8-Pro_MIR8_MIR1__2__1"/>
        </joint>
        
        <joint name="${prefix}_Rigid 26" type="fixed">
          <origin xyz="0.079889 0.025958 ${sign*0.0}" rpy="0 0 0"/>
          <parent link="${prefix}_RMD-X8-Pro_MIR8_MIR1__2__1"/>
          <child link="${prefix}_elbow-hangar_1"/>
        </joint>
        
        <joint name="${prefix}_Rigid 27" type="fixed">
          <origin xyz="0.079861 0.026042 ${sign*-0.035}" rpy="0 0 0"/>
          <parent link="${prefix}_RMD-X8-Pro_MIR8_MIR1__2__1"/>
          <child link="${prefix}_elbow-hangar1_1"/>
        </joint>
        
        <joint name="${prefix}_Rigid 28" type="fixed">
          <origin xyz="0.040033 -0.029021 ${sign*-0.035}" rpy="0 0 0"/>
          <parent link="${prefix}_RMD-X8-Pro_MIR8_MIR1__2__1"/>
          <child link="${prefix}_power-mount-arm_1"/>
        </joint>
        
        <joint name="${prefix}_Rigid 29" type="fixed">
          <origin xyz="0.008009 -0.006919 ${sign*-0.0065}" rpy="0 0 0"/>
          <parent link="${prefix}_power-mount-arm_1"/>
          <child link="${prefix}_fan-mount_1"/>
        </joint>
        
        <joint name="${prefix}_elbow_joint" type="revolute">
          <origin xyz="0.039944 0.012979 ${sign*-0.037}" rpy="0 0 0"/>
          <parent link="${prefix}_RMD-X8-Pro_MIR8_MIR1__2__1"/>
          <child link="${prefix}_bicep-motor-mate_1"/>
          <axis xyz="0.0 0.0 ${sign * -1.0}"/>
          <limit upper="${PI}" lower="${-PI}" velocity="10.0" effort="100.0"/>
        </joint>
        
        <joint name="${prefix}_Rigid 31" type="fixed">
          <origin xyz="0.011713 0.058846 ${sign*0.0025}" rpy="0 0 0"/>
          <parent link="${prefix}_bicep-motor-mate_1"/>
          <child link="${prefix}_6mm-bearing_1"/>
        </joint>
        
        <joint name="${prefix}_Revolute32" type="revolute">
            <origin xyz="0.0 0.0 ${sign*0.005}" rpy="0 0 0"/>
            <parent link="${prefix}_6mm-bearing_1"/>
            <child link="${prefix}_bicep_1"/>
            <axis xyz="0.0 0.0 1.0"/>
            <limit upper="${PI}" lower="${-PI}" velocity="10.0" effort="100.0"/>
          </joint>
        
        <joint name="${prefix}_Revolute 33" type="continuous">
          <origin xyz="0.04913 0.009283 ${sign*-0.005}" rpy="0 0 0"/>
          <parent link="${prefix}_bicep_1"/>
          <child link="${prefix}_6mm-bearing__9__1"/>
          <axis xyz="0.0 0.0 -1.0"/>
        </joint>
        
        <joint name="${prefix}_Rigid 34" type="fixed">
          <origin xyz="0.0 0.0 ${sign*0.005}" rpy="0 0 0"/>
          <parent link="${prefix}_6mm-bearing__9__1"/>
          <child link="${prefix}_straight-tendon_1"/>
        </joint>
        
        <joint name="${prefix}_Rigid 35" type="fixed">
          <origin xyz="0.009962 0.032686 ${sign*-0.0005}" rpy="0 0 0"/>
          <parent link="${prefix}_elbow-hangar_1"/>
          <child link="${prefix}_6mm-bearing__1__1"/>
        </joint>
        
        <joint name="${prefix}_Rigid 36" type="fixed">
          <origin xyz="0.009963 0.032687 ${sign*0.0005}" rpy="0 0 0"/>
          <parent link="${prefix}_elbow-hangar1_1"/>
          <child link="${prefix}_6mm-bearing__5__1"/>
        </joint>
        
        <joint name="${prefix}_Rigid 38" type="fixed">
          <origin xyz="0.031304 0.011589 ${sign*-0.0005}" rpy="0 0 0"/>
          <parent link="${prefix}_elbow-hangar_1"/>
          <child link="${prefix}_6mm-bearing__2__1"/>
        </joint>
        
        <joint name="${prefix}_Rigid 39" type="fixed">
          <origin xyz="0.0 0.0 ${sign*-0.005}" rpy="0 0 0"/>
          <parent link="${prefix}_6mm-bearing__2__1"/>
          <child link="${prefix}_elbow-bridge-rear__1__1"/>
        </joint>
        
        <joint name="${prefix}_Rigid 40" type="fixed">
          <origin xyz="0.031304 0.011589 ${sign*0.0005}" rpy="0 0 0"/>
          <parent link="${prefix}_elbow-hangar1_1"/>
          <child link="${prefix}_6mm-bearing__6__1"/>
        </joint>
        
        <joint name="${prefix}_Revolute 41" type="continuous">
          <origin xyz="0.0 0.0 ${sign*0.0}" rpy="0 0 0"/>
          <parent link="${prefix}_6mm-bearing__2__1"/>
          <child link="${prefix}_elbow-rear-hanger__1__1"/>
          <axis xyz="-0.0 -0.0 1.0"/>
        </joint>
        
        <joint name="${prefix}_Revolute 42" type="continuous">
          <origin xyz="0.0 0.0 ${sign*0.0}" rpy="0 0 0"/>
          <parent link="${prefix}_6mm-bearing__6__1"/>
          <child link="${prefix}_elbow-rear-hanger_1"/>
          <axis xyz="0.0 0.0 -1.0"/>
        </joint>
        
        <joint name="${prefix}_Revolute 43" type="continuous">
          <origin xyz="0.050222 -0.052218 ${sign*-0.005}" rpy="0 0 0"/>
          <parent link="${prefix}_straight-tendon_1"/>
          <child link="${prefix}_6mm-bearing__7__1"/>
          <axis xyz="0.0 0.0 -1.0"/>
        </joint>
        
        <joint name="${prefix}_Revolute 44" type="continuous">
          <origin xyz="0.050222 -0.052218 ${sign*0.029}" rpy="0 0 0"/>
          <parent link="${prefix}_straight-tendon_1"/>
          <child link="${prefix}_6mm-bearing__4__1"/>
          <axis xyz="-0.0 -0.0 1.0"/>
        </joint>
        
        <joint name="${prefix}_Rigid 45" type="fixed">
          <origin xyz="0.0 0.0 ${sign*0.0}" rpy="0 0 0"/>
          <parent link="${prefix}_6mm-bearing__4__1"/>
          <child link="${prefix}_forearm-elbow-motor-bracket-inner2_1"/>
        </joint>
        
        <joint name="${prefix}_Rigid 46" type="fixed">
          <origin xyz="0.01256 0.037977 ${sign*0.0}" rpy="0 0 0"/>
          <parent link="${prefix}_forearm-elbow-motor-bracket-inner2_1"/>
          <child link="${prefix}_6mm-bearing__3__1"/>
        </joint>
        
        <joint name="${prefix}_Rigid 48" type="fixed">
          <origin xyz="0.0 0.0 ${sign*-0.005}" rpy="0 0 0"/>
          <parent link="${prefix}_6mm-bearing__3__1"/>
          <child link="${prefix}_elbow-bridge-rear_1"/>
        </joint>
        
        <joint name="${prefix}_Rigid 49" type="fixed">
          <origin xyz="0.009468 0.047487 ${sign*0.0115}" rpy="0 0 0"/>
          <parent link="${prefix}_forearm-elbow-motor-bracket-inner2_1"/>
          <child link="${prefix}_second-forearm-motor-strap_1"/>
        </joint>
        
        <joint name="${prefix}_Rigid 50" type="fixed">
          <origin xyz="0.026695 -0.00193 ${sign*0.000944}" rpy="0 0 0"/>
          <parent link="${prefix}_second-forearm-motor-strap_1"/>
          <child link="${prefix}_RMD-X8-Pro_MIR8_MIR1__4__1"/>
        </joint>
        
        <joint name="${prefix}_Rigid 51" type="fixed">
          <origin xyz="-0.006482 0.019975 ${sign*-0.064631}" rpy="0 0 0"/>
          <parent link="${prefix}_RMD-X8-Pro_MIR8_MIR1__4__1"/>
          <child link="${prefix}_fore-arm-bicep-motor-attatch_1"/>
        </joint>
        
        <joint name="${prefix}_Rigid 52" type="fixed">
          <origin xyz="-0.020213 -0.018046 ${sign*0.006687}" rpy="0 0 0"/>
          <parent link="${prefix}_fore-arm-bicep-motor-attatch_1"/>
          <child link="${prefix}_forearm-elbow-motor-bracket-inner_1"/>
        </joint>
        
        <joint name="${prefix}_Rigid 53" type="fixed">
          <origin xyz="0.003086 -0.009512 ${sign*0.0115}" rpy="0 0 0"/>
          <parent link="${prefix}_forearm-elbow-motor-bracket-inner_1"/>
          <child link="${prefix}_6mm-bearing__8__1"/>
        </joint>
        
        <joint name="${prefix}_wrist_roll" type="revolute">
          <origin xyz="0.0392 -0.000924 ${sign*-0.039944}" rpy="0 0 0"/>
          <parent link="${prefix}_RMD-X8-Pro_MIR8_MIR1__4__1"/>
          <child link="${prefix}_shoulder-ex-al-interface_1"/>
          <axis xyz="0.951172 0.308661 0.0"/>
          <limit upper="${PI}" lower="${-PI}" velocity="10.0" effort="100.0"/>
        </joint>
        
        <joint name="${prefix}_Rigid 56" type="fixed">
          <origin xyz="0.013867 0.013962 ${sign*-0.015588}" rpy="0 0 0"/>
          <parent link="${prefix}_shoulder-ex-al-interface_1"/>
          <child link="${prefix}_shoulder-roll-al-mot_MIR1__3__1"/>
        </joint>
        
        <joint name="${prefix}_Rigid 57" type="fixed">
          <origin xyz="0.013867 0.013962 ${sign*0.015589}" rpy="0 0 0"/>
          <parent link="${prefix}_shoulder-ex-al-interface_1"/>
          <child link="${prefix}_shoulder-roll-al-mot_MIR1_1"/>
        </joint>
        
        <joint name="${prefix}_Rigid 58" type="fixed">
          <origin xyz="0.016645 0.005401 ${sign*0.0}" rpy="0 0 0"/>
          <parent link="${prefix}_shoulder-ex-al-interface_1"/>
          <child link="${prefix}_2020_100mm__10__1"/>
        </joint>
        
        <joint name="${prefix}_Rigid 59" type="fixed">
          <origin xyz="0.0 0.0 ${sign*0.0}" rpy="0 0 0"/>
          <parent link="${prefix}_2020_100mm__10__1"/>
          <child link="${prefix}_top-bracket-servo-strap_1"/>
        </joint>
        
        <joint name="${prefix}_Rigid 60" type="fixed">
          <origin xyz="0.029129 0.030059 ${sign*-0.01515}" rpy="0 0 0"/>
          <parent link="${prefix}_top-bracket-servo-strap_1"/>
          <child link="${prefix}_MG995_1"/>
        </joint>
        
        <joint name="${prefix}_Rigid 61" type="fixed">
          <origin xyz="0.039855 -0.002994 ${sign*-0.0196}" rpy="0 0 0"/>
          <parent link="${prefix}_top-bracket-servo-strap_1"/>
          <child link="${prefix}_MG995__4__1"/>
        </joint>
        
        <joint name="${prefix}_Rigid 62" type="fixed">
          <origin xyz="0.041228 -0.007227 ${sign*0.01515}" rpy="0 0 0"/>
          <parent link="${prefix}_top-bracket-servo-strap_1"/>
          <child link="${prefix}_MG995__3__1"/>
        </joint>
        
        <joint name="${prefix}_Rigid 63" type="fixed">
          <origin xyz="0.030502 0.025826 ${sign*0.0196}" rpy="0 0 0"/>
          <parent link="${prefix}_top-bracket-servo-strap_1"/>
          <child link="${prefix}_MG995__5__1"/>
        </joint>
        
        <joint name="${prefix}_Rigid 64" type="fixed">
          <origin xyz="0.0 0.0 ${sign*0.0}" rpy="0 0 0"/>
          <parent link="${prefix}_2020_100mm__10__1"/>
          <child link="${prefix}_2020_100mm__11__1"/>
        </joint>
        
        <joint name="${prefix}_Rigid 65" type="fixed">
          <origin xyz="0.142662 0.046295 ${sign*0.0}" rpy="0 0 0"/>
          <parent link="${prefix}_2020_100mm__11__1"/>
          <child link="${prefix}_top-bracket-servo-strap__1__1"/>
        </joint>
        
        <joint name="${prefix}_Rigid 66" type="fixed">
          <origin xyz="-0.015139 0.011015 ${sign*-0.0196}" rpy="0 0 0"/>
          <parent link="${prefix}_top-bracket-servo-strap__1__1"/>
          <child link="${prefix}_MG995__2__1"/>
        </joint>
        
        <joint name="${prefix}_Rigid 67" type="fixed">
          <origin xyz="-0.004413 -0.022039 ${sign*-0.01515}" rpy="0 0 0"/>
          <parent link="${prefix}_top-bracket-servo-strap__1__1"/>
          <child link="${prefix}_MG995__6__1"/>
        </joint>
        
        <joint name="${prefix}_Rigid 68" type="fixed">
          <origin xyz="-0.005787 -0.017806 ${sign*0.0196}" rpy="0 0 0"/>
          <parent link="${prefix}_top-bracket-servo-strap__1__1"/>
          <child link="${prefix}_MG995__1__1"/>
        </joint>
        
        <joint name="${prefix}_Rigid 69" type="fixed">
          <origin xyz="-0.016513 0.015247 ${sign*0.01515}" rpy="0 0 0"/>
          <parent link="${prefix}_top-bracket-servo-strap__1__1"/>
          <child link="${prefix}_MG995__7__1"/>
        </joint>
        
        <joint name="${prefix}_Rigid 70" type="fixed">
          <origin xyz="0.011983 -0.004518 ${sign*0.011}" rpy="0 0 0"/>
          <parent link="${prefix}_bicep-shoulder-bracket-exal__1__1"/>
          <child link="${prefix}_multiplex-stack-flat_1"/>
        </joint>

        <gazebo>
            <plugin name="gazebo_ros" filename="libgazebo_ros_api_plugin.so"/>
            <joint name="${prefix}_Revolute37_gz" type="revolute">
              <pose relative_to="${prefix}_RMD-X8-Pro_MIR8_MIR1__3__1">0.1464 0.07711 ${sign*-0.0065} 0 0 0</pose>
              <parent>${prefix}_straight-tendon_1</parent>
              <child>${prefix}_6mm-bearing__5__1</child>
      
              <axis>
                <xyz> 0 0 1</xyz>
              </axis>
              <limit>
                <lower>${-PI}</lower>
                <upper>${PI}</upper>
                <effort>100.0</effort>
                <velocity>10.0</velocity>
              </limit>
              <dynamics>
                <damping>10.0</damping>
                <friction>0.50</friction>
              </dynamics>
            </joint>
            
            <joint name="${prefix}_Revolute47_gz" type="revolute">
              <pose relative_to="${prefix}_elbow-rear-hanger__1__1">0.05237 0.02931 ${sign*-0.029} 0 0 0</pose>
              <!-- <pose relative_to="${prefix}_elbow-rear-hanger__1__1">0.07143 -0.002652 ${sign*-0.029} 0 0 0</pose> -->
              <parent>${prefix}_elbow-rear-hanger_1</parent>
              <child>${prefix}_6mm-bearing__8__1</child>
      
              <axis>
                <xyz> 0 0 1</xyz>
              </axis>
              <limit>
                <lower>${-PI}</lower>
                <upper>${PI}</upper>
              </limit>
              <dynamics>
                <damping>1.0</damping>
                <friction>0.5</friction>
              </dynamics>
            </joint>
      
            
            <joint name="${prefix}_Recolute48_gz" type="revolute">
              <pose relative_to="${prefix}_elbow-rear-hanger__1__1">0.05237 0.02932 ${sign*-0.005} 0 0 0</pose>
                <parent>${prefix}_elbow-rear-hanger__1__1</parent>
                <child>${prefix}_6mm-bearing__3__1</child>
      
              <axis>
                <xyz> 0 0 -1</xyz>
              </axis>
              <limit>
                <lower>${-PI}</lower>
                <upper>${PI}</upper>
              </limit>
      
              <dynamics>
                <damping>2.0</damping>
                <friction>0.10</friction>
              </dynamics>
            </joint>

          </gazebo>
        

    </xacro:macro>
</robot>